Workbook
Name print_area_mi2: #REF!
Name print_area_mi2: #REF!
Name サイズ: [1]凡例!$C$2:$C$4
Name 工事件名１: [1]凡例!$D$2:$D$25
Name 工事件名２: [1]凡例!$E$2:$E$25
Name 他支所名: [1]凡例!$B$3:$B$28
Name 多摩７５０管理図: #REF!
Name 多摩７５０管理図: #REF!
Name 多摩７５０管理図２: #REF!
Name 多摩７５０管理図２: #REF!
Name 年号: [1]凡例!$A$3:$A$4

Sheet ISO台帳(多)
A1: 整理番号 | B1: 受注日 | C1: 受注月 | D1: 受注番号 | E1: 工事番号 | F1: ＮＣ区分 | G1: 担当者 | H1: 工 事 場 所 | I1: 住所（行政区） | J1: 件名 | K1: 件名区分 | L1: 現場日 | M1: 顧客引渡 実施日 | N1: 納品月 | O1: 繁閑調整 | P1: 委託業者名(外注) | Q1: 外注納品 実施日 | R1: 外注支払月 | S1: 外注費 | T1: 委託業者名(外注)2 | U1: 外注発注日2 | V1: 外注納品 予定日2 | W1: 外注納品 実施日2 | X1: 部門長2 | Y1: 外注支払月2 | Z1: 外注費2 | AA1: 入金月 | AB1: 請求書発行番号 | AC1: 入金月（月のみ） | AD1: 事務所/分室 | AE1: 精算 グループ | AF1: 金額 | AG1: 精算延長 | AH1: 繁閑調整金 | AI1: 列1 | AN1: =SUM(AG:AG) -> 26922
A2: 1 | B2: 44943 | C2: 1 | D2: 230733 | E2: 313- | F2: 多摩 | G2: 森田 雄次 | H2: 立川市栄町3-24 | I2: 立川市 | J2: 入取替 | K2: 1 | L2: 済み | M2: 45789 | N2: 5 | AB2: 20038437
A3: 2 | B3: 44426 | C3: 8 | D3: 231196 | E3: 311-242018X | F3: 西部 | G3: 今村 公人 | H3: 調布市布田2-43 | I3: 調布市 | J3: 入取替 | K3: 2 | L3: 済み | M3: 45561 | N3: 9 | AA3: 25.6 | AB3: 10013732 | AC3: 6 | AE3: 35 | AF3: 405178 | AG3: 205
A4: 3 | B4: 44426 | C4: 8 | D4: 231197 | E4: 311-242017X | F4: 西部 | G4: 今村 公人 | H4: 調布市布田2-21 | I4: 調布市 | J4: 入取替 | K4: 3 | L4: 済み | M4: 45714 | N4: 2 | AA4: 25.6 | AB4: 10013731 | AC4: 6 | AE4: 35 | AF4: 285695 | AG4: 219
A5: 4 | B5: 45210 | C5: 10 | D5: 330379 | E5: 313-386726A | F5: 多摩 | G5: 下川原 聡 | H5: 国分寺市西恋ヶ窪1-27 | I5: 国分寺 | J5: 他受（道路） | K5: 4 | L5: 済み | M5: 45806 | N5: 5 | AA5: 25.8 | AB5: 30027118 | AC5: 8 | AE5: 35 | AF5: 235960 | AG5: 60
A6: 5 | B6: 45210 | C6: 10 | D6: 330390 | E6: 311-142008X | F6: 西部 | G6: 早川 浩太郎 | H6: 調布市小島町1-8 | I6: 調布市 | J6: 占用位置変更 | K6: 5 | L6: 済み | M6: 45597 | N6: 11 | AB6: 30027456
A7: 6 | B7: 45216 | C7: 10 | D7: 330396 | E7: 313-特殊見積 | F7: 多摩 | G7: 上松 一雄 | H7: 東大和市高木3-270 | I7: 東大和 | J7: 奈良橋川仮設検討 | K7: 6 | L7: 済み | M7: 保留 | T7: 上松 | U7: 45800 | V7: 45868 | W7: 45965 | X7: 5/23蓮見 | Y7: 25.11 | AA7: 25.12 | AB7: 30041042 | AC7: 12 | AE7: 35 | AF7: 1881952 | AG7: 718
A8: 7 | B8: 45264 | C8: 12 | D8: 330525 | E8: 313-486716A | F8: 多摩 | G8: 今村 公人 | H8: 東大和市上北台1-1066 | I8: 東大和 | J8: 他受（道路） | K8: 7 | L8: 済み | M8: 45790 | N8: 5 | AA8: 25.9 | AB8: 30034488 | AC8: 9 | AE8: 35 | AF8: 294195 | AG8: 22
A9: 8 | B9: 45285 | C9: 12 | D9: 330604 | E9: 313-486721C | F9: 多摩 | G9: 早川 浩太郎 | H9: 東村山市本町1-16 | I9: 東村山 | J9: 他受（道路・線路上マンション立ち退き後） | K9: 8 | L9: 済み | M9: 45595 | N9: 10 | AB9: 30037695
A10: 9 | B10: 45315 | C10: 1 | D10: 330667 | E10: 313-443032X | F10: 多摩 | G10: 吉田 真人 | H10: 小平市花小金井1-17 | I10: 小平市 | J10: 入取替 | K10: 9 | L10: 済み | M10: 45875 | N10: 8 | O10: 神奈川 | AA10: 25.8 | AB10: 30040336 | AC10: 8 | AE10: 40 | AF10: 247191 | AG10: 57 | AH10: 247191
A11: 10 | B11: 45315 | C11: 1 | D11: 330668 | E11: 313-443033X | F11: 多摩 | G11: 上野 謙二 | H11: 小平市小川西町3-12 | I11: 小平市 | J11: 入取替 | K11: 10 | L11: 済み | T11: 上野 | U11: 45450 | V11: 45534 | X11: 6/7蓮見 | AB11: 30040333
A12: 11 | B12: 45315 | C12: 1 | D12: 330669 | E12: 313-443034X | F12: 多摩 | G12: 上野 謙二 | H12: 小平市仲町291 | I12: 小平市 | J12: 入取替 | K12: 11 | L12: 済み | T12: 上野 | U12: 45542 | V12: 45534 | X12: 9/7蓮見 | AB12: 30040331
A13: 12 | B13: 45327 | C13: 2 | D13: 330698 | E13: 313-443015X | F13: 多摩 | G13: 堀田 正法 | H13: 八王子市めじろ台1-41 | I13: 八王子 | J13: 入取替 | K13: 12 | L13: 済み | M13: 45959 | N13: 10 | AA13: 25.10 | AB13: 30042237 | AC13: 10 | AE13: 40 | AF13: 211789 | AG13: 52
A14: 13 | B14: 45327 | C14: 2 | D14: 330702 | E14: 313-443038X | F14: 多摩 | G14: 若林 実 | H14: 国分寺市泉町1-10 | I14: 国分寺 | J14: 入取替 | K14: 13 | L14: 済み | P14: 若林 | AB14: 30042241
A15: 14 | B15: 45327 | C15: 2 | D15: 330703 | E15: 313-443048X | F15: 多摩 | G15: 立川 太貴 | H15: 東大和市南街2-101 | I15: 東大和 | J15: 入取替 | K15: 14 | L15: 済み | M15: 45874 | N15: 8 | AB15: 30042193
A16: 15 | B16: 45327 | C16: 2 | D16: 330705 | E16: 313-443044X | F16: 多摩 | G16: 小林 哲也 | H16: 国立市西2-3 | I16: 国立市 | J16: 入取替 | K16: 15 | L16: 済み | AB16: 30042262
A17: 16 | B17: 45327 | C17: 2 | D17: 330706 | E17: 313-443043X | F17: 多摩 | G17: 若林 実 | H17: 国立市中1-14 | I17: 国立市 | J17: 入取替 | K17: 16 | L17: 済み | P17: 若林 | AB17: 30042265
A18: 17 | B18: 45327 | C18: 2 | D18: 330708 | E18: 313-443049X | F18: 多摩 | G18: 堀田 正法 | H18: 東村山市萩山町2-20 | I18: 東村山 | J18: 入取替 | K18: 17 | L18: 済み | AB18: 30042270
A19: 18 | B19: 45330 | C19: 2 | D19: 330725 | E19: 313-443039X | F19: 多摩 | G19: 森田 雄次 | H19: 国分寺市東元町2-14 | I19: 国分寺 | J19: 入取替 | K19: 18 | L19: 済み | M19: 45735 | N19: 3 | P19: 望月 | Q19: 45380 | R19: 24.3 | AA19: 25.6 | AB19: 50014381 | AC19: 6 | AE19: 35 | AF19: 376749 | AG19: 164
A20: 19 | B20: 45330 | C20: 2 | D20: 330726 | E20: 313-443040X | F20: 多摩 | G20: 森田 雄次 | H20: 国分寺市東元町2-7 | I20: 国分寺 | J20: 入取替 | K20: 19 | L20: 済み | M20: 45742 | N20: 3 | P20: 望月 | Q20: 45380 | R20: 24.3 | AA20: 25.6 | AB20: 50014379 | AC20: 6 | AE20: 35 | AF20: 389123 | AG20: 162
A21: 20 | B21: 45366 | C21: 3 | D21: 330855 | E21: 313-特殊見積 | F21: 多摩 | G21: 森田 雄次 | H21: 日野市程久保895 | I21: 日野市 | J21: 橋梁構造確認 | K21: 20 | L21: 済み | M21: 45387 | N21: 4 | AA21: 24.5 | AB21: 30047922 | AC21: 5
A22: 21 | B22: 45413 | C22: 5 | D22: 330939 | E22: 313-471713X | F22: 多摩 | G22: 森田 雄次 | H22: 多摩市関戸5-16 | I22: 多摩市 | J22: 他受（水道） | K22: 21 | L22: 済み | M22: 45842 | N22: 7 | AA22: 25.8 | AB22: 40016344 | AC22: 8 | AE22: 35 | AF22: 387826 | AG22: 57
A23: 22 | B23: 45446 | C23: 6 | D23: 430005 | E23: 313-419058X | F23: 多摩 | G23: 立川 太貴 | H23: 八王子市大和田町4-25 | I23: 八王子 | J23: 変更 | K23: 22 | L23: 済み | M23: 45447 | N23: 6 | AB23: 40039408
A24: 23 | B24: 45453 | C24: 6 | D24: 430040 | E24: 313-443051X | F24: 多摩 | G24: 今村 公人 | H24: 国分寺市東元町3-21-42 | I24: 国分寺 | J24: 入取替 | K24: 23 | L24: 済み | M24: 保留 | AB24: 40040658
A25: 24 | B25: 45455 | C25: 6 | D25: 430052 | E25: 313-419088X | F25: 多摩 | G25: 小林 哲也 | H25: 八王子市館町522 都 | I25: 八王子 | J25: 需要 | K25: 24 | L25: 済み | M25: 45870 | N25: 8 | AA25: 25.9 | AB25: 40041401 | AC25: 9 | AE25: 35 | AF25: 423726 | AG25: 300
A26: 25 | B26: 45457 | C26: 6 | D26: 430061 | E26: 313-476802A | F26: 多摩 | G26: 今村 公人 | H26: 八王子市館町1879 | I26: 八王子 | J26: 他受・本設戻し | K26: 25 | L26: 済み | P26: 日鉄 | Q26: 45891 | R26: 25.9 | S26: 280000 | AB26: 40041471
A27: 26 | B27: 45470 | C27: 6 | D27: 430097 | E27: 313-541017X | F27: 多摩 | G27: 小林 哲也 | H27: 小平市大沼町4-43 | I27: 小平市 | J27: 入取替（CCB事業中） | K27: 26 | L27: 済み | AB27: 40043649
A28: 27 | B28: 45469 | C28: 6 | D28: 430106 | E28: 313-541004X | F28: 多摩 | G28: 今村 公人 | H28: 八王子市中野上町5-1 | I28: 八王子 | J28: 入取替（DG） | K28: 27 | L28: 済み | M28: 45730 | N28: 3 | AB28: 40043488
A29: 28 | B29: 45469 | C29: 6 | D29: 430107 | E29: 313-541005X | F29: 多摩 | G29: 今村 公人 | H29: 八王子市中野上町5-5 | I29: 八王子 | J29: 入取替（DG） | K29: 28 | L29: 済み | AB29: 40043490
A30: 29 | B30: 45469 | C30: 6 | D30: 430108 | E30: 313-541007X | F30: 多摩 | G30: 若林 実 | H30: 八王子市中野上町4-43 | I30: 八王子 | J30: 入取替（DG） | K30: 29 | L30: 済み | M30: 45716 | N30: 2 | P30: 若林 | Q30: 45716 | R30: 25.2 | AB30: 40043491
A31: 30 | B31: 45469 | C31: 6 | D31: 430109 | E31: 313-541008X | F31: 多摩 | G31: 下川原 聡 | H31: 八王子市中野上町4-40 | I31: 八王子 | J31: 入取替（DG） | K31: 30 | L31: 済み | M31: 45702 | N31: 2 | AA31: 26.1 | AB31: 40043493 | AC31: 1 | AE31: 35 | AF31: 395407 | AG31: 137
A32: 31 | B32: 45469 | C32: 6 | D32: 430111 | E32: 313-541011X | F32: 多摩 | G32: 小林 哲也 | H32: 八王子市中野山王3-1 | I32: 八王子 | J32: 入取替（DG） | K32: 31 | L32: 済み | M32: 45719 | N32: 3 | AB32: 40043498
A33: 32 | B33: 45469 | C33: 6 | D33: 430112 | E33: 313-541012X | F33: 多摩 | G33: 今津 輝 | H33: 八王子市中野山王3-18 | I33: 八王子 | J33: 入取替（DG） | K33: 32 | L33: 済み | M33: 45735 | N33: 3 | T33: 今津 | U33: 45539 | V33: 45626 | W33: 45735 | X33: 9/4蓮見 | AB33: 40043500
A34: 33 | B34: 45469 | C34: 6 | D34: 430113 | E34: 313-541013X | F34: 多摩 | G34: 今津 輝 | H34: 八王子市中野山王3-20 | I34: 八王子 | J34: 入取替（DG） | K34: 33 | L34: 済み | M34: 45735 | N34: 3 | T34: 今津 | U34: 45539 | V34: 45626 | W34: 45735 | X34: 9/4蓮見 | AB34: 40043503
A35: 34 | B35: 45469 | C35: 6 | D35: 430114 | E35: 313-541014X | F35: 多摩 | G35: 三日尻 道男 | H35: 八王子市大和田町6-12 | I35: 八王子 | J35: 入取替（DG） | K35: 34 | L35: 済み | M35: 45723 | N35: 3 | AA35: 26.2 | AB35: 40043506 | AC35: 2 | AE35: 35 | AF35: 603682 | AG35: 240
A36: 35 | B36: 45469 | C36: 6 | D36: 430115 | E36: 313-541015X | F36: 多摩 | G36: 堀田 正法 | H36: 八王子市台町3-19 | I36: 八王子 | J36: 入取替（DG） | K36: 35 | L36: 済み | M36: 45707 | N36: 2 | AA36: 25.12 | AB36: 40043508 | AC36: 12 | AE36: 35 | AF36: 335532 | AG36: 69
A37: 36 | B37: 45477 | C37: 7 | D37: 430127 | E37: 313-443054X | F37: 多摩 | G37: 立川 太貴 | H37: 東村山市青葉町2-5 | I37: 東村山 | J37: 入取替 | K37: 36 | L37: 済み | M37: 45898 | N37: 8 | P37: 望月 | Q37: 45826 | R37: 25.6 | AA37: 26.1 | AB37: 40044701 | AC37: 1 | AE37: 35 | AF37: 1158817 | AG37: 453
A38: 37 | B38: 45484 | C38: 7 | D38: 430191 | E38: 313-541020F | F38: 多摩 | G38: 下川原 聡 | H38: 国分寺市東元町2-20 | I38: 国分寺 | J38: 入取替（DG） | K38: 37 | L38: 済み | M38: 45614 | N38: 11 | AA38: 25.8 | AB38: 40045739 | AC38: 8 | AE38: 301 | AF38: 426843 | AG38: 159
A39: 38 | B39: 45506 | C39: 8 | D39: 430193 | E39: 313-186724X | F39: 多摩 | G39: 今村 公人 | H39: 八王子市館町1097-15 | I39: 八王子 | J39: バルブかさ上げ申請 | K39: 38 | L39: 済み | M39: 保留 | AB39: 40048094
A40: 39 | B40: 45510 | C40: 8 | D40: 430199 | E40: 313-586717X | F40: 多摩 | G40: 今村 公人 | H40: 八王子市大船町182 | I40: 八王子 | J40: 他受（無償） | K40: 39 | AB40: 40048340
...

Sheet ISO台帳(西)
A1: 整理番号 | B1: 受注日 | C1: 受注月 | D1: 受注番号 | E1: 工事番号 | F1: ＮＣ区分 | G1: 担当者 | H1: 工 事 場 所 | I1: 住所（行政区） | J1: 件名 | K1: 件名区分 | L1: 現場日 | M1: 顧客引渡 実施日 | N1: 納品月 | O1: 繁閑調整 | P1: 委託業者名(外注) | Q1: 外注納品 実施日 | R1: 部所長 | S1: 外注支払月 | T1: 外注費 | U1: 委託業者名(外注)2 | V1: 外注発注日2 | W1: 外注納品 予定日2 | X1: 外注納品 実施日2 | Y1: 部所長2 | Z1: 外注支払月2 | AA1: 外注費2 | AB1: 入金月 | AC1: 請求書発行番号 | AD1: 入金月（月のみ） | AE1: 事務所/分室 | AF1: 精算 グループ | AG1: 金額 | AH1: 精算延長 | AI1: 繁閑調整金
A2: 1 | B2: 43920 | C2: 3 | D2: 910835 | E2: 311-077201X | F2: 西部 | G2: 上松 一雄 | H2: 三鷹市牟礼2-5-15 | I2: 三鷹市 | J2: 他受 架管本設 | L2: - | M2: 中止 | V2: 44690 | AB2: - | AC2: 90053007
A3: 2 | B3: 44657 | C3: 4 | D3: 110753 | E3: 311-243011I | F3: 西部 | G3: 茂木 政寛 | H3: 世田谷区下馬1-52 | I3: 世田谷 | J3: 入取替（KF） | L3: - | M3: 45439 | N3: 5 | P3: エステー | Q3: 44736 | R3: 4/28古川 | S3: 22.6 | AC3: 20000545
A4: 3 | B4: 44662 | C4: 4 | D4: 110761 | E4: 311-243061I | F4: 西部 | G4: 鈴木 怜於名 | H4: 世田谷区下馬6-49 | I4: 世田谷 | J4: 入取替（KF） | L4: - | M4: 45433 | N4: 5 | P4: エステー | Q4: 44706 | R4: 4/22古川 | S4: 22.5 | AC4: 20000881
A5: 4 | B5: 44890 | C5: 11 | D5: 210310 | E5: 311-343035X | F5: 西部 | G5: 上松 一雄 | H5: 三鷹市上連雀1-10-4 | I5: 三鷹市 | J5: 入取替（KF） | L5: - | M5: 45531 | N5: 8 | AC5: 20031677
A6: 5 | B6: 44890 | C6: 11 | D6: 210313 | E6: 311-343038X | F6: 西部 | G6: 上松 一雄 | H6: 三鷹市井の頭2-29 | I6: 三鷹市 | J6: 入取替（KF） | L6: - | M6: 45544 | N6: 9 | V6: 45873 | X6: 45897 | Z6: 25.8 0 | AA6: 123888 0 | AC6: 20031681
A7: 6 | B7: 44890 | C7: 11 | D7: 210314 | E7: 311-343039X | F7: 西部 | G7: 上松 一雄 | H7: 三鷹市下連雀4-8 | I7: 三鷹市 | J7: 入取替（KF） | L7: - | M7: 45531 | N7: 8 | AC7: 20031682
A8: 7 | B8: 45082 | C8: 6 | D8: 310008 | E8: 113-442674X | F8: 南部 | G8: 小林 昌志 | H8: 大田区田園調布5-17-22 | I8: 大田区 | J8: 入取替（KF） | M8: 45854 | N8: 7 | P8: 共立 | Q8: 45320 | R8: 12/20古川 | S8: 24.2 | AB8: 25.7 | AC8: 30009457 | AD8: 7 | AF8: 16 | AG8: 262168 | AH8: 170
A9: 8 | B9: 45082 | C9: 6 | D9: 310016 | E9: 113-442689X | F9: 南部 | G9: 小林 昌志 | H9: 大田区山王2-12-2 | I9: 大田区 | J9: 入取替（KF）(区) | M9: 45862 | N9: 7 | P9: 共立 | Q9: 45350 | R9: 1/23古川 | S9: 24.3 | AB9: 25.7 | AC9: 30009336 | AD9: 7 | AF9: 16 | AG9: 175939 | AH9: 52
A10: 9 | B10: 45082 | C10: 6 | D10: 310020 | E10: 113-442694X | F10: 南部 | G10: 小林 昌志 | H10: 大田区大森中2-4-17 | I10: 大田区 | J10: 入取替（KF）(区) | M10: 45869 | N10: 7 | P10: 共立 | Q10: 45350 | R10: 1/23古川 | S10: 24.3 | AB10: 25.8 | AC10: 30009847 | AD10: 8 | AF10: 16 | AG10: 196626 | AH10: 65
A11: 10 | B11: 45121 | C11: 7 | D11: 310170 | E11: 311-142237X | F11: 西部 | G11: 鈴木 怜於名 | H11: 世田谷区南烏山6-25 | I11: 世田谷 | J11: DF 特殊件名20号 | L11: 不要 | M11: 中止 | AC11: 請求なし
A12: 11 | B12: 45323 | C12: 2 | D12: 310791 | E12: 311-443206X | F12: 西部 | G12: 上松 一雄 | H12: 武蔵野市境南町3-4 | I12: 武蔵野 | J12: 入取替（KF） | L12: - | N12: 1 | AC12: 30041918
A13: 12 | B13: 45324 | C13: 2 | D13: 310795 | E13: 311-443202X | F13: 西部 | G13: 上松 一雄 | H13: 三鷹市上連雀2-17 | I13: 三鷹市 | J13: 入取替（KF） | L13: - | M13: 45687 | N13: 1 | AC13: 30042113
A14: 13 | B14: 45324 | C14: 2 | D14: 310796 | E14: 311-443203X | F14: 西部 | G14: 上松 一雄 | H14: 三鷹市井の頭2-34 | I14: 三鷹市 | J14: 入取替（KF） | L14: - | M14: 45735 | N14: 3 | AC14: 30042114
A15: 14 | B15: 45358 | C15: 3 | D15: 310913 | E15: 113-490119X | F15: 南部 | G15: 茂木 政寛 | H15: 大田区上池台2-32-1 | I15: 大田区 | J15: 入取替 | M15: 45504 | N15: 7 | P15: 共立 | Q15: 45398 | R15: 4/2古川 | S15: 24.4 | AB15: - | AC15: 中止・請求なし
A16: 15 | B16: 45370 | C16: 3 | D16: 310943 | E16: 113-541176X | F16: 南部 | G16: 藤田 雄也 | H16: 大田区南雪谷1-19-8 | I16: 大田区 | J16: 入取替（DG） | M16: 45741 | N16: 3 | AB16: 25.12 | AC16: 30048213 | AD16: 12 | AF16: 16 | AG16: 745712 | AH16: 71
A17: 16 | B17: 45422 | C17: 5 | D17: 311086 | E17: 113-Z40063X | F17: 南部 | G17: 藤田 雄也 | H17: 大田区大森西2-20 | I17: 大田区 | J17: 供給改善 概算 | M17: 45866 | N17: 7 | AB17: 25.7 | AC17: 40022462 | AD17: 7 | AF17: 16 | AG17: 108628
A18: 17 | B18: 45426 | C18: 5 | D18: 311096 | E18: 113-Z00154X | F18: 南部 | G18: 古川 智基 | H18: 大田区平和島1-2 | I18: 大田区 | J18: 他受 | M18: 45492 | N18: 7 | P18: 共立 | Q18: 45462 | R18: 5/28古川 | S18: 24.6 | AC18: 40026514
A19: 18 | B19: 45434 | C19: 5 | D19: 311126 | E19: 113-541508X | F19: 南部 | G19: 藤田 雄也 | H19: 大田区西六郷1-5-3 | I19: 大田区 | J19: 入取替（DG）(2025年度施工) (住宅政策本部) | L19: 済 | M19: 46052 | N19: 1 | P19: 共立 | Q19: 45628 | R19: 10/29古川 | S19: 24.12 | AB19: 26.2 | AC19: 40038020 | AD19: 2 | AF19: 16 | AG19: 216867 | AH19: 57
A20: 19 | B20: 45447 | C20: 6 | D20: 410002 | E20: 113-541507X | F20: 南部 | G20: 黒須 雄也 | H20: 大田区西蒲田7-60-9 | I20: 大田区 | J20: 入取替（DG） | M20: 45771 | N20: 4 | P20: 共立 | Q20: 45601 | R20: 9/30古川 | S20: 24.11 | AB20: - | AC20: 中止・請求なし
A21: 20 | B21: 45447 | C21: 6 | D21: 410004 | E21: 113-590023X | F21: 南部 | G21: 古川 智基 | H21: 大田区蒲田3-24-4 | I21: 大田区 | J21: 入取替（DG） | M21: 45869 | N21: 7 | P21: 共立 | Q21: 45628 | R21: 10/29古川 | S21: 24.12 | AB21: 25.8 | AC21: 40039521 | AD21: 8 | AF21: 16 | AG21: 156845 | AH21: 10
A22: 21 | B22: 45447 | C22: 6 | D22: 410005 | E22: 113-590024X | F22: 南部 | G22: 古川 智基 | H22: 大田区羽田4-4-29 | I22: 大田区 | J22: 入取替（DG） | M22: 45866 | N22: 7 | P22: 共立 | Q22: 45643 | R22: 12/2古川 | S22: 24.12 | AB22: 25.7 | AC22: 40039475 | AD22: 7 | AF22: 16 | AG22: 204317 | AH22: 10
A23: 22 | B23: 45461 | C23: 6 | D23: 410040 | E23: 311-541010X | F23: 西部 | G23: 茂木 政寛 | H23: 東久留米市滝山6-2 | I23: 東久留 | J23: 入取替（DG） | L23: - | N23: 1 | P23: 共立 | Q23: 45611 | R23: 9/30古川 | S23: 24.11 | AC23: 40042030
A24: 23 | B24: 45461 | C24: 6 | D24: 410041 | E24: 311-541011X | F24: 西部 | G24: 茂木 政寛 | H24: 東久留米市滝山6-2 | I24: 東久留 | J24: 入取替（DG） | L24: - | N24: 1 | P24: 共立 | Q24: 45611 | R24: 9/30古川 | S24: 24.11 | AC24: 40042029
A25: 24 | B25: 45461 | C25: 6 | D25: 410050 | E25: 311-641019X | F25: 西部 | G25: 鈴木 怜於名 | H25: 東久留米市南沢3-1 | I25: 東久留 | J25: 入取替（DG） | L25: - | M25: 45785 | N25: 5 | P25: 共立 | Q25: 45517 | R25: 7/9古川 | S25: 24.8 | AC25: 40042036
A26: 25 | B26: 45461 | C26: 6 | D26: 410051 | E26: 311-641021X | F26: 西部 | G26: 上松 一雄 | H26: 東久留米市南沢3-10 | I26: 東久留 | J26: 入取替（DG） | L26: - | M26: 45687 | N26: 1 | AC26: 40042038
A27: 26 | B27: 45461 | C27: 6 | D27: 410052 | E27: 311-641028X | F27: 西部 | G27: 小林 昌志 | H27: 東久留米市滝山6-1 | I27: 東久留 | J27: 入取替（DG） | L27: - | M27: 46080 | N27: 2 | P27: 共立 | Q27: 45540 | R27: 7/31古川 | S27: 24.9 | AB27: 26.2 | AC27: 40042039 | AD27: 2 | AF27: 35 | AG27: 263525
A28: 27 | B28: 45461 | C28: 6 | D28: 410053 | E28: 311-641029X | F28: 西部 | G28: 小林 昌志 | H28: 東久留米市滝山6-1 | I28: 東久留 | J28: 入取替（DG） | L28: - | M28: 45721 | N28: 3 | P28: 共立 | Q28: 45540 | R28: 7/31古川 | S28: 24.9 | AC28: 40042041
A29: 28 | B29: 45461 | C29: 6 | D29: 410054 | E29: 311-641030X | F29: 西部 | G29: 小林 昌志 | H29: 東久留米市滝山7-19 | I29: 東久留 | J29: 入取替（DG） | L29: - | M29: 45754 | N29: 4 | P29: 共立 | Q29: 45540 | R29: 7/31古川 | S29: 24.9 | AC29: 40042043
A30: 29 | B30: 45476 | C30: 7 | D30: 410090 | E30: 311-641012F | F30: 西部 | G30: 安藤 嶺 | H30: 東久留米市八幡町3-3 | I30: 東久留 | J30: FLEX | L30: 済 | M30: 45708 | N30: 2 | P30: 共立 | Q30: 45565 | R30: 8/27古川 | S30: 24.10 | AC30: 日鉄P＆E
A31: 30 | B31: 45476 | C31: 7 | D31: 410091 | E31: 311-641014F | F31: 西部 | G31: 安藤 嶺 | H31: 東久留米市滝山4-11 | I31: 東久留 | J31: FLEX | L31: 済 | M31: 45636 | N31: 12 | P31: 共立 | Q31: 45568 | R31: 8/27古川 | S31: 24.10 | AB31: 25.11 | AC31: 日鉄P＆E | AD31: 11 | AF31: 301 | AG31: 405546 | AH31: 153
A32: 31 | B32: 45476 | C32: 7 | D32: 410092 | E32: 311-641016F | F32: 西部 | G32: 茂木 政寛 | H32: 東久留米市前沢5-11 | I32: 東久留 | J32: FLEX | L32: 済 | M32: 45632 | N32: 12 | P32: 共立 | Q32: 45601 | R32: 9/30古川 | S32: 24.11 | AB32: 25.9 | AC32: 日鉄P＆E | AD32: 9 | AF32: 301 | AG32: 434548 | AH32: 231
A33: 32 | B33: 45476 | C33: 7 | D33: 410093 | E33: 311-641018F | F33: 西部 | G33: 鈴木 怜於名 | H33: 東久留米市中央町1-1 | I33: 東久留 | J33: FLEX | L33: 済 | M33: 45625 | N33: 11 | AC33: 日鉄P＆E
A34: 33 | B34: 45476 | C34: 7 | D34: 410094 | E34: 311-641020F | F34: 西部 | G34: 鈴木 怜於名 | H34: 東久留米市南沢3-5 | I34: 東久留 | J34: FLEX | L34: 済 | M34: 45628 | N34: 12 | AC34: 日鉄P＆E
A35: 34 | B35: 45476 | C35: 7 | D35: 410095 | E35: 311-641022F | F35: 西部 | G35: 鈴木 怜於名 | H35: 東久留米市本町4-13 | I35: 東久留 | J35: FLEX | L35: 済 | M35: 45635 | N35: 12 | P35: 共立 | Q35: 45517 | R35: 7/9古川 | S35: 24.8 | AB35: 25.8 | AC35: 日鉄P＆E | AD35: 8 | AF35: 301 | AG35: 516860 | AH35: 227
A36: 35 | B36: 45476 | C36: 7 | D36: 410097 | E36: 311-641032F | F36: 西部 | G36: 茂木 政寛 | H36: 東久留米市本町4-7 | I36: 東久留 | J36: FLEX | L36: 済 | M36: 45642 | N36: 12 | P36: 共立 | Q36: 45505 | R36: 7/9古川 | S36: 24.8 | AC36: 日鉄P＆E
A37: 36 | B37: 45476 | C37: 7 | D37: 410098 | E37: 311-641033F | F37: 西部 | G37: 茂木 政寛 | H37: 東久留米市本町4-9 | I37: 東久留 | J37: FLEX | L37: 済 | M37: 45911 | N37: 9 | P37: 共立 | Q37: 45505 | R37: 7/9古川 | S37: 24.8 | AC37: 日鉄P＆E
A38: 37 | B38: 45482 | C38: 7 | D38: 410124 | E38: 311-641025X | F38: 西部 | G38: 茂木 政寛 | H38: 三鷹市野崎1-3 | I38: 三鷹市 | J38: 入取替（DG） | L38: - | M38: 45687 | N38: 1 | P38: 共立 | Q38: 45567 | R38: 8/27古川 | S38: 24.10 | AC38: 40045342
A39: 38 | B39: 45502 | C39: 7 | D39: 410164 | E39: 311-542032F | F39: 西部 | G39: 茂木 政寛 | H39: 東久留米市小山2-3-4 | I39: 東久留 | J39: FLEX | L39: - | M39: 45639 | N39: 12 | P39: 共立 | Q39: 45596 | R39: 10/15古川 | S39: 24.11 | AB39: 25.10 | AC39: 日鉄P＆E | AD39: 10 | AF39: 301 | AG39: 643253 | AH39: 33
A40: 39 | B40: 45519 | C40: 8 | D40: 410213 | E40: 311-142237X | F40: 西部 | G40: 鈴木 怜於名 | H40: 世田谷区南烏山6-25 | I40: 世田谷 | J40: DF | L40: 不要 | M40: 45800 | N40: 5 | AB40: 25.8 | AC40: 40049285 | AD40: 8 | AF40: 35 | AG40: 84016
...

Sheet ISO台帳(神)
A1: 整理番号 | B1: 受注日 | C1: 受注月 | D1: 受注番号 | E1: 工事番号 | F1: ＮＣ区分 | G1: 担当者 | H1: 工 事 場 所 | I1: 住所（行政区） | J1: 件名 | K1: 件名区分 | L1: 現場日 | M1: 顧客引渡 実施日 | N1: 納品月 | O1: 繁閑調整 | P1: 委託業者名(外注) | Q1: 外注納品 実施日 | R1: 外注支払月 | S1: 外注費 | T1: 委託業者名(外注)2 | U1: 外注発注日2 | V1: 外注納品 予定日2 | W1: 外注納品 実施日2 | X1: 部門長2 | Y1: 外注支払月2 | Z1: 外注費2 | AA1: 入金月 | AB1: 請求書発行番号 | AC1: 入金月（月のみ） | AD1: 事務所/分室 | AE1: 精算 グループ | AF1: 金額 | AG1: 精算延長 | AH1: 繁閑調整金 | AI1: 事業所 | AL1: =AF176+AF508+AF511+AF582+AF608+AF732 -> 778454
A2: 1 | B2: 45762 | C2: 4 | D2: 420995 | E2: 512 | F2: 神奈川 | G2: 吉田・有賀 | H2: 川崎市 | I2: 川崎市 | J2: 道調資料作成・修正作業 | L2: 不要 | M2: 45819 | N2: 6 | AA2: 25.6 | AB2: 520604 | AC2: 6 | AD2: 神 | AE2: 100 | AF2: 61154 | AI2: 神奈川
A3: 2 | B3: 45810 | C3: 6 | D3: 420996 | E3: 512 | F3: 神奈川 | G3: 鈴木 照子 | H3: 川崎市 | I3: 川崎市 | J3: 供給管申請（ROADIS） | L3: 不要 | M3: 45838 | N3: 6 | AA3: 25.6 | AB3: 520601 | AC3: 6 | AD3: 神 | AE3: 100 | AF3: 261773 | AI3: 神奈川
A4: 3 | B4: 45810 | C4: 6 | D4: 420997 | E4: 512 | F4: 神奈川 | G4: 鈴木 照子 | H4: 川崎市 | I4: 川崎市 | J4: 供給管申請（手申請/GALILEOⅡ） | L4: 不要 | M4: 45838 | N4: 6 | AA4: 25.6 | AB4: 520602 | AC4: 6 | AD4: 神 | AE4: 100 | AF4: 193701 | AI4: 神奈川
A5: 4 | B5: 45810 | C5: 6 | D5: 420998 | E5: 512 | F5: 神奈川 | G5: 鈴木 照子 | H5: 川崎市 | I5: 川崎市 | J5: 申請業務 | L5: 不要 | M5: 45834 | N5: 6 | AA5: 25.6 | AB5: 520603 | AC5: 6 | AD5: 神 | AE5: 100 | AF5: 48041 | AI5: 神奈川
A6: 5 | B6: 45810 | C6: 6 | D6: 420999 | E6: 553 | F6: 神奈川 | G6: 鈴木 照子 | H6: 川崎市 | I6: 川崎市 | J6: 漏洩修理他申請（ROADIS） | L6: 不要 | M6: 45834 | N6: 6 | AA6: 25.6 | AB6: 50009679 | AC6: 6 | AD6: 神 | AE6: 50 | AF6: 196296 | AI6: 神奈川
A7: 7 | B7: 45089 | C7: 6 | D7: 320046 | E7: 513-119143X | F7: 神奈川 | G7: 米山 直人 | H7: 高津区溝口2-14 | I7: 高津区 | J7: 変更申請 | L7: 済 | M7: 46055 | N7: 2 | AA7: 26.2 | AB7: 20031347 | AC7: 2 | AD7: 湘 | AE7: 21 | AF7: 14680 | AI7: 神奈川
A8: 8 | B8: 45219 | C8: 10 | D8: 320712 | E8: 513-435003K | F8: 神奈川 | G8: 佐藤 竜 | H8: 高津区梶ヶ谷6-8 | I8: 高津区 | J8: 供給改善A（中圧） | L8: 済 | M8: 45259 | N8: 11 | AB8: 30028858 | AI8: 神奈川
A9: 10 | B9: 45264 | C9: 12 | D9: 320895 | E9: 513-435003Q | F9: 神奈川 | G9: 水上 知輝 | H9: 麻生区上麻生6-29 | I9: 麻生区 | J9: 供給改善A | L9: 済 | M9: 45471 | N9: 6 | AB9: 30034703 | AI9: 神奈川
A10: 11 | B10: 45343 | C10: 2 | D10: 321169 | E10: 513-481002T | F10: 神奈川 | G10: 山田 敏雄 | H10: 麻生区片平4-5 | I10: 麻生区 | J10: 他受（無償）（道路工事） | L10: 済 | M10: 45856 | N10: 7 | P10: みつば | Q10: 45381 | R10: 24.3 | AA10: 25.7 | AB10: 30044283 | AC10: 7 | AD10: 神 | AE10: 27 | AF10: 660123 | AG10: 333 | AI10: 神奈川
A11: 12 | B11: 45398 | C11: 4 | D11: 321463 | E11: 512-553101J | F11: 神奈川 | G11: 佐藤 竜 | H11: 神奈川区三枚町698 | I11: 神奈川 | J11: ＤＧ入取替（大規模一括件名） | L11: 済 | M11: 45504 | N11: 7 | AA11: 25.7 | AB11: 40006161 | AC11: 7 | AD11: 神 | AE11: 27 | AF11: 114810 | AG11: 35 | AI11: 神奈川
A12: 13 | B12: 45083 | C12: 6 | D12: 321477 | E12: 513-311002A | F12: 神奈川 | G12: 水上 知輝 | H12: 中原区小杉町1 | I12: 中原区 | J12: 工区分割 | L12: 済 | M12: 45771 | N12: 4 | AA12: 25.6 | AB12: 30009593 | AC12: 6 | AD12: 神 | AE12: 27 | AF12: 296772 | AG12: 79 | AI12: 神奈川
A13: 14 | B13: 45400 | C13: 4 | D13: 321483 | E13: 513-419024X | F13: 神奈川 | G13: 有賀 真之介 | H13: 宮前区平4-17 | I13: 宮前区 | J13: 道路復旧 | L13: 済 | M13: 中止 | AB13: 40008390 | AI13: 神奈川
A14: 15 | B14: 45453 | C14: 6 | D14: 420040 | E14: 513-553113J | F14: 神奈川 | G14: 廣瀬 達 | H14: 宮前区南野川3-12 | I14: 宮前区 | J14: ＤＧ入取替（大規模一括件名） | L14: 済 | M14: 45688 | N14: 1 | P14: 共立 | Q14: 45652 | R14: 25.1 | AA14: 25.6 | AB14: 40040654 | AC14: 6 | AD14: 神 | AE14: 27 | AF14: 515612 | AG14: 203 | AI14: 神奈川
A15: 16 | B15: 45453 | C15: 6 | D15: 420045 | E15: 513-553118J | F15: 神奈川 | G15: 有賀 真之介 | H15: 中原区井田2-33 | I15: 中原区 | J15: ＤＧ入取替（大規模一括件名） | L15: 済 | M15: 45728 | N15: 3 | P15: 共立 | Q15: 45652 | R15: 25.1 | AB15: 40040677 | AI15: 神奈川
A16: 17 | B16: 45453 | C16: 6 | D16: 420052 | E16: 512-553124J | F16: 神奈川 | G16: 青柳 亨 | H16: 鶴見区鶴見中央1-22 | I16: 鶴見区 | J16: ＤＧ入取替（大規模一括件名） | L16: 済 | M16: 45750 | N16: 4 | AA16: 25.6 | AB16: 40040748 | AC16: 6 | AD16: 神 | AE16: 27 | AF16: 289758 | AG16: 84 | AI16: 神奈川
A17: 18 | B17: 45455 | C17: 6 | D17: 420060 | E17: 512-553122J | F17: 神奈川 | G17: 廣瀬 達 | H17: 鶴見区矢向1-13 | I17: 鶴見区 | J17: ＤＧ入取替（大規模一括件名） | L17: 済 | M17: 45856 | N17: 7 | P17: みつば | Q17: 45569 | R17: 24.1 | AA17: 25.8 | AB17: 40041083 | AC17: 8 | AD17: 神 | AE17: 27 | AF17: 382105 | AG17: 229 | AI17: 神奈川
A18: 19 | B18: 45455 | C18: 6 | D18: 420069 | E18: 513-653111J | F18: 神奈川 | G18: 有賀 真之介 | H18: 川崎区小田4-27 | I18: 川崎区 | J18: ＤＧ入取替（大規模一括件名） | L18: 済 | M18: 45768 | N18: 4 | P18: みつば | Q18: 45681 | R18: 25.1 | AA18: 25.6 | AB18: 40041182 | AC18: 6 | AD18: 神 | AE18: 27 | AF18: 372606 | AG18: 263 | AI18: 神奈川
A19: 20 | B19: 45455 | C19: 6 | D19: 420071 | E19: 513-653103J | F19: 神奈川 | G19: 水上 知輝 | H19: 高津区梶ヶ谷2-12 | I19: 高津区 | J19: ＤＧ入取替（大規模一括件名） | L19: 済 | M19: 45751 | N19: 4 | O19: 設備 | P19: 本社 | Q19: 45589 | AB19: 40041100 | AI19: 神奈川
A20: 21 | B20: 45455 | C20: 6 | D20: 420075 | E20: 513-653108J | F20: 神奈川 | G20: 青柳 亨 | H20: 中原区今井仲町11 | I20: 中原区 | J20: ＤＧ入取替（大規模一括件名） | L20: 済 | M20: 45737 | N20: 3 | P20: みつば | Q20: 45713 | R20: 25.2 | AA20: 25.7 | AB20: 40041136 | AC20: 7 | AD20: 神 | AE20: 27 | AF20: 376692 | AG20: 254 | AI20: 神奈川
A21: 22 | B21: 45455 | C21: 6 | D21: 420076 | E21: 513-653109J | F21: 神奈川 | G21: 有賀 真之介 | H21: 川崎区伊勢町6 | I21: 川崎区 | J21: ＤＧ入取替（大規模一括件名） | L21: 済 | M21: 45806 | N21: 5 | P21: みつば | Q21: 45713 | R21: 25.2 | AA21: 26.1 | AB21: 40041141 | AC21: 1 | AD21: 神 | AE21: 27 | AF21: 363920 | AG21: 365 | AI21: 神奈川
A22: 23 | B22: 45460 | C22: 6 | D22: 420088 | E22: 512-553131J | F22: 神奈川 | G22: 山田 敏雄 | H22: 神奈川区松見町3-532 | I22: 神奈川 | J22: ＤＧ入取替（大規模一括件名） | L22: 済 | M22: 45744 | N22: 3 | P22: 共立 | Q22: 45631 | R22: 24.12 | AA22: 25.8 | AB22: 40041684 | AC22: 8 | AD22: 神 | AE22: 27 | AF22: 600548 | AG22: 454 | AI22: 神奈川
A23: 24 | B23: 45460 | C23: 6 | D23: 420092 | E23: 512-553136J | F23: 神奈川 | G23: 佐藤 竜 | H23: 神奈川区西寺尾2-24 | I23: 神奈川 | J23: ＤＧ入取替（大規模一括件名） | L23: 済 | M23: 45721 | N23: 3 | AA23: 25.11 | AB23: 40041705 | AC23: 11 | AD23: 神 | AE23: 27 | AF23: 331739 | AG23: 168 | AI23: 神奈川
A24: 25 | B24: 45460 | C24: 6 | D24: 420107 | E24: 512-553145J | F24: 神奈川 | G24: 佐藤 竜 | H24: 青葉区美しが丘1-19 | I24: 青葉区 | J24: ＤＧ入取替（大規模一括件名） | L24: 済 | M24: 45743 | N24: 3 | O24: 西部 | P24: みつば | Q24: 45652 | R24: 25.1 | AA24: 25.7 | AB24: 40041900 | AC24: 7 | AD24: 神 | AE24: 27 | AF24: 434052 | AG24: 426 | AH24: 237593 | AI24: 神奈川
A25: 26 | B25: 45462 | C25: 6 | D25: 420111 | E25: 512-653113J | F25: 神奈川 | G25: 廣瀬 達 | H25: 神奈川区旭ヶ丘23 | I25: 神奈川 | J25: ＤＧ入取替（大規模一括件名） | L25: 済 | M25: 45645 | N25: 12 | P25: 共立 | Q25: 45568 | R25: 24.1 | AA25: 25.6 | AB25: 40042110 | AC25: 6 | AD25: 神 | AE25: 27 | AF25: 481908 | AG25: 364 | AI25: 神奈川
A26: 27 | B26: 45461 | C26: 6 | D26: 420113 | E26: 512-653115J | F26: 神奈川 | G26: 山田 智史 | H26: 神奈川区神奈川本町7 | I26: 神奈川 | J26: FLEX | L26: 済 | M26: 45853 | N26: 7 | P26: 共立 | Q26: 45716 | R26: 25.3 | AA26: 25.9 | AB26: 50011434 | AC26: 9 | AD26: 湘 | AE26: 301 | AF26: 381779 | AG26: 187 | AI26: 神奈川
A27: 28 | B27: 45461 | C27: 6 | D27: 420114 | E27: 512-653116J | F27: 神奈川 | G27: 廣瀬 達 | H27: 神奈川区六角橋6-24 | I27: 神奈川 | J27: ＤＧ入取替（大規模一括件名） | L27: 済 | M27: 45805 | N27: 5 | P27: みつば | Q27: 45713 | R27: 25.2 | AA27: 25.10 | AB27: 40042126 | AC27: 10 | AD27: 神 | AE27: 27 | AF27: 398145 | AG27: 198 | AI27: 神奈川
A28: 29 | B28: 45462 | C28: 6 | D28: 420115 | E28: 512-653120J | F28: 神奈川 | G28: 廣瀬 達 | H28: 青葉区桜台26 | I28: 青葉区 | J28: ＤＧ入取替（大規模一括件名） | L28: 済 | M28: 45721 | N28: 3 | P28: みつば | Q28: 45652 | R28: 25.1 | AA28: 25.6 | AB28: 40042161 | AC28: 6 | AD28: 神 | AE28: 27 | AF28: 395132 | AG28: 257 | AI28: 神奈川
A29: 30 | B29: 45462 | C29: 6 | D29: 420117 | E29: 512-653121J | F29: 神奈川 | G29: 廣瀬 達 | H29: 青葉区桜台38 | I29: 青葉区 | J29: ＤＧ入取替（大規模一括件名） | L29: 済 | M29: 45715 | N29: 2 | AA29: 25.7 | AB29: 40042277 | AC29: 7 | AD29: 神 | AE29: 27 | AF29: 373060 | AG29: 209 | AI29: 神奈川
A30: 31 | B30: 45462 | C30: 6 | D30: 420118 | E30: 512-653122J | F30: 神奈川 | G30: 山田 智史 | H30: 青葉区榎が丘7 | I30: 青葉区 | J30: ＤＧ入取替（大規模一括件名） | L30: 済 | M30: 45796 | N30: 5 | P30: 共立 | Q30: 45629 | R30: 24.12 | AA30: 25.6 | AB30: 40042283 | AC30: 6 | AD30: 湘 | AE30: 27 | AF30: 369152 | AG30: 246 | AI30: 神奈川
A31: 32 | B31: 45462 | C31: 6 | D31: 420119 | E31: 512-653123J | F31: 神奈川 | G31: 有賀 真之介 | H31: 青葉区市ヶ尾町1169 | I31: 青葉区 | J31: ＤＧ入取替（大規模一括件名） | L31: 済 | M31: 45868 | N31: 7 | P31: 共立 | Q31: 45716 | R31: 25.3 | AB31: 40042315 | AI31: 神奈川
A32: 33 | B32: 45464 | C32: 6 | D32: 420153 | E32: 513-553125F | F32: 神奈川 | G32: 山田 智史 | H32: 幸区東古市場121 | I32: 幸区東 | J32: FLEX | L32: 済 | M32: 45602 | N32: 11 | AA32: 25.8 | AB32: 40042450 | AC32: 8 | AD32: 湘 | AE32: 301 | AF32: 301077 | AG32: 55 | AI32: 神奈川
A33: 34 | B33: 45471 | C33: 6 | D33: 420214 | E33: 513-553140P | F33: 神奈川 | G33: 山田 智史 | H33: 川崎区駅前本町4-2 | I33: 川崎区 | J33: ＤＧ入取替 | L33: 済 | M33: 45594 | N33: 10 | AA33: 25.10 | AB33: 40044019 | AC33: 10 | AD33: 湘 | AE33: 27 | AF33: 207850 | AG33: 24 | AI33: 神奈川
A34: 35 | B34: 45476 | C34: 7 | D34: 420238 | E34: 513-553144P | F34: 神奈川 | G34: 青柳 亨 | H34: 中原区新丸子町922 | I34: 中原区 | J34: ＤＧ入取替 | L34: 済 | M34: 45706 | N34: 2 | AA34: 25.10 | AB34: 40044587 | AC34: 10 | AD34: 神 | AE34: 27 | AF34: 232196 | AG34: 52 | AI34: 神奈川
A35: 36 | B35: 45476 | C35: 7 | D35: 420241 | E35: 513-653107J | F35: 神奈川 | G35: 山田 智史 | H35: 中原区今井仲町12 | I35: 中原区 | J35: ＤＧ入取替（大規模一括件名） | L35: 済 | M35: 45806 | N35: 5 | P35: みつば | Q35: 45713 | R35: 25.2 | AA35: 25.9 | AB35: 40044610 | AC35: 9 | AD35: 湘 | AE35: 27 | AF35: 361117 | AG35: 278 | AI35: 神奈川
A36: 37 | B36: 45539 | C36: 9 | D36: 420465 | E36: 512-542153J | F36: 神奈川 | G36: 山田 智史 | H36: 鶴見区上末吉1-21 | I36: 鶴見区 | J36: 申請書作成 | L36: 済 | M36: 45813 | N36: 6 | AA36: 25.6 | AB36: 40051389 | AC36: 6 | AD36: 湘 | AE36: 27 | AF36: 115333 | AI36: 神奈川
A37: 39 | B37: 45602 | C37: 11 | D37: 420677 | E37: 512-544101Y | F37: 神奈川 | G37: 山田 智史 | H37: 鶴見区弁天町2 | I37: 鶴見区 | J37: バルブ取替 | L37: 済 | M37: 45761 | N37: 4 | AA37: 25.6 | AB37: 40058400 | AC37: 6 | AD37: 湘 | AE37: 27 | AF37: 195035 | AG37: 10 | AI37: 神奈川
A38: 40 | B38: 45602 | C38: 11 | D38: 420678 | E38: 513-544407Y | F38: 神奈川 | G38: 佐藤 竜 | H38: 多摩区枡形2-3 | I38: 多摩区 | J38: ガバナ取替 | L38: 済 | M38: 45804 | N38: 5 | AA38: 25.7 | AB38: 40058405 | AC38: 7 | AD38: 神 | AE38: 27 | AF38: 263684 | AG38: 12 | AI38: 神奈川
A39: 42 | B39: 45623 | C39: 11 | D39: 420751 | E39: 513-532103X | F39: 神奈川 | G39: 髙橋 篤史 | H39: 高津区下作延5-9 | I39: 高津区 | J39: 供給改善（A) | L39: 済 | M39: 45811 | N39: 6 | AA39: 25.7 | AB39: 40060840 | AC39: 7 | AD39: 神 | AE39: 27 | AF39: 106466 | AI39: 神奈川
A40: 44 | B40: 45639 | C40: 12 | D40: 420804 | E40: 512-541002A | F40: 神奈川 | G40: 安藤 俊輔 | H40: 青葉区新石川2-13 | I40: 青葉区 | J40: 中圧入取替（MA化） | L40: 済 | M40: 45827 | N40: 6 | P40: 共立 | Q40: 45686 | R40: 25.2 | AA40: 26.1 | AB40: 40062724 | AC40: 1 | AD40: 湘 | AE40: 27 | AF40: 700528 | AG40: 338 | AI40: 神奈川
...

Sheet 杭台帳(多)
A1: 整理番号 | B1: 工事番号 | C1: 住 所 | D1: NC区分 | E1: 住所（行政区） | F1: 受注日 | G1: 受注月 | H1: 受注番号 | I1: 区分 | J1: 発行番号 | K1: 外注先 | L1: 納品月 | M1: 外注 発注月 | N1: 外注納品月 | O1: 工期 | P1: 製本受領 | Q1: 多摩フリ3 | R1: 外注支払月 | S1: 外注支払月(月のみ) | T1: 外注支払額 | U1: 入金月 | V1: 入金月（月のみ） | W1: 精算 グループ | X1: 入金額 | Y1: 復元杭引渡日 | Z1: 製本受領2 | AA1: 市提出 | AB1: 杭購入金額 | AF1: =SUM(X:X) -> 1.2674893e+08
A2: 1 | B2: 313-343065X | C2: 国分寺市本多5-25 | D2: 多摩 | E2: 国分寺 | F2: 44936 | G2: 1 | H2: 233513 | I2: 事前 | J2: 20036825 | K2: みつば | L2: 6 | M2: 2 | N2: 5 | P2: 45827 | R2: 45828 | S2: 6 | T2: 162000 | U2: 25.6 | V2: 6 | W2: 40 | X2: 273547
A3: 2 | B3: 313-343014X | C3: 立川市栄町3-24 | D3: 多摩 | E3: 立川市 | F3: 44942 | G3: 1 | H3: 233581 | I3: 事前 | J3: 20038319 | K3: みつば | L3: 7 | M3: 5 | N3: 7 | R3: 45861 | S3: 7 | T3: 85490 | U3: 25.7 | V3: 7 | W3: 40 | X3: 173514
A4: 3 | B4: 313-343017X | C4: 東村山市秋津町5-6 | D4: 多摩 | E4: 東村山 | F4: 44942 | G4: 1 | H4: 233590 | I4: 事前 | J4: 20038404
A5: 4 | B5: 313-242114E | C5: 八王子市中野山王1-5 | D5: 多摩 | E5: 八王子 | H5: 234013 | I5: 事前 | Y5: 45742 | AA5: 46035
A6: 5 | B6: 313-042102X | C6: 八王子市平岡町36 | D6: 多摩 | E6: 八王子 | H6: 330155 | I6: 事前 | AB6: 7050
A7: 6 | B7: 313-986704X | C7: 八王子市南町3 | D7: 多摩 | E7: 八王子 | H7: 330185 | I7: 事前 | Z7: 45908 | AA7: 45909
A8: 7 | B8: 313-486721C | C8: 東村山市本町1-16 | D8: 多摩 | E8: 東村山 | F8: 45309 | G8: 1 | H8: 330732 | I8: 事前 | J8: 30037925
A9: 8 | B9: 313-443034X | C9: 小平市仲町291 | D9: 多摩 | E9: 小平市 | F9: 45313 | G9: 1 | H9: 330737 | I9: 事前 | J9: 30040330
A10: 9 | B10: 313-443033X | C10: 小平市小川西町3-12 | D10: 多摩 | E10: 小平市 | F10: 45313 | G10: 1 | H10: 330738 | I10: 事前 | J10: 30040332
A11: 10 | B11: 313-443032X | C11: 小平市花小金井1-17 | D11: 多摩 | E11: 小平市 | F11: 45313 | G11: 1 | H11: 330739 | I11: 事前 | J11: 30040335 | K11: 共立 | L11: 9 | M11: 9 | N11: 9 | R11: 45922 | S11: 9 | T11: 76420 | U11: 25.9 | V11: 9 | W11: 40 | X11: 165891
A12: 11 | B12: 313-443031X | C12: 小平市学園東町3-1 | D12: 多摩 | E12: 小平市 | F12: 45313 | G12: 1 | H12: 330740 | I12: 事前 | J12: 30040338 | K12: みつば | L12: 7 | M12: 5 | N12: 7 | P12: 45873 | R12: 45861 | S12: 7 | T12: 90480 | U12: 25.7 | V12: 7 | W12: 40 | X12: 195028
A13: 12 | B13: 313-443038X | C13: 国分寺市泉町1-10 | D13: 多摩 | E13: 国分寺 | F13: 45327 | G13: 2 | H13: 330772 | I13: 事前 | J13: 30042239
A14: 13 | B14: 313-443043X | C14: 国立市中1-14 | D14: 多摩 | E14: 国立市 | F14: 45327 | G14: 2 | H14: 330773 | I14: 事前 | J14: 30042264
A15: 14 | B15: 313-443044X | C15: 国立市西2-3 | D15: 多摩 | E15: 国立市 | F15: 45327 | G15: 2 | H15: 330774 | I15: 事前 | J15: 30042261
A16: 15 | B16: 313-443015X | C16: 八王子市めじろ台1-41 | D16: 多摩 | E16: 八王子 | F16: 45327 | G16: 2 | H16: 330776 | I16: 事前 | J16: 30042236 | K16: 共立 | L16: 12 | M16: 11 | N16: 12 | R16: 46022 | S16: 12 | T16: 42920 | U16: 25.12 | V16: 12 | W16: 40 | X16: 87307
A17: 16 | B17: 313-443048X | C17: 東大和市南街2-101 | D17: 多摩 | E17: 東大和 | F17: 45328 | G17: 2 | H17: 330785 | I17: 事前 | J17: 30042191 | K17: 共立 | L17: 10 | M17: 9 | N17: 10 | U17: 25.1 | V17: 10 | W17: 40 | X17: 138194
A18: 17 | B18: 313-443040X | C18: 国分寺市東元町2-7 | D18: 多摩 | E18: 国分寺 | F18: 45328 | G18: 2 | H18: 330786 | I18: 事前 | J18: 30042215 | K18: みつば | L18: 6 | M18: 5 | N18: 6 | P18: 45834 | R18: 45828 | S18: 6 | T18: 254000 | U18: 25.6 | V18: 6 | W18: 40 | X18: 433462
A19: 18 | B19: 313-443039X | C19: 国分寺市東元町2-14 | D19: 多摩 | E19: 国分寺 | F19: 45328 | G19: 2 | H19: 330787 | I19: 事前 | J19: 30042219 | K19: みつば | L19: 6 | M19: 5 | N19: 6 | P19: 45834 | R19: 45828 | S19: 6 | T19: 242000 | U19: 25.6 | V19: 6 | W19: 40 | X19: 400443
A20: 19 | B20: 313-443049X | C20: 東大和市萩山町2-20 | D20: 多摩 | E20: 東大和 | F20: 45328 | G20: 2 | H20: 330791 | I20: 事前 | J20: 30042269
A21: 20 | B21: 313-242014M | C21: 国分寺市東恋ヶ窪2-23 | D21: 多摩 | E21: 国分寺 | F21: 45866 | G21: 7 | H21: 330811 | I21: 事前 | J21: 50021651 | K21: 共立 | L21: 8 | M21: 7 | N21: 7 | R21: 45891 | S21: 8 | T21: 57880 | U21: 25.8 | V21: 8 | W21: 40 | X21: 121416 | Y21: 45344
A22: 21 | B22: 313-486723A | C22: 多摩市鶴牧5-31 | D22: 多摩 | E22: 多摩市 | F22: 45356 | G22: 3 | H22: 330847 | I22: 事前 | J22: 30045999
A23: 22 | B23: 313-471713X | C23: 多摩市関戸5-16 | D23: 多摩 | E23: 多摩市 | F23: 45420 | G23: 5 | H23: 330987 | I23: 事前 | J23: 40018132 | K23: みつば | L23: 11 | M23: 7 | N23: 11 | O23: 46027 | R23: 45991 | S23: 11 | T23: 41750 | U23: 25.11 | V23: 11 | W23: 40 | X23: 86360
A24: 23 | B24: 313-342033M | C24: 日野市東平山1-7 | D24: 多摩 | E24: 日野市 | H24: 330997 | I24: 事前
A25: 24 | B25: 313-342043X | C25: 小平市学園西町3-23 | D25: 多摩 | E25: 小平市 | H25: 331087 | I25: 事前
A26: 25 | B26: 313-443051X | C26: 国分寺市東元町3-21 | D26: 多摩 | E26: 国分寺 | F26: 45454 | G26: 6 | H26: 430050 | I26: 事前 | J26: 40040729
A27: 26 | B27: 313-541001X | C27: 八王子市中野上町4-28 | D27: 多摩 | E27: 八王子 | F27: 45469 | G27: 6 | H27: 430100 | I27: 事前 | J27: 40043441 | K27: みつば | L27: 11 | M27: 7 | N27: 11 | R27: 45991 | S27: 11 | T27: 177010 | U27: 25.11 | V27: 11 | W27: 40 | X27: 366419
A28: 27 | B28: 313-541003X | C28: 八王子市中野上町5-10 | D28: 多摩 | E28: 八王子 | F28: 45469 | G28: 6 | H28: 430101 | I28: 事前 | J28: 40043446 | K28: みつば | L28: 11 | M28: 7 | N28: 11 | P28: 46001 | R28: 45991 | S28: 11 | T28: 207925 | U28: 25.11 | V28: 11 | W28: 40 | X28: 362384
A29: 28 | B29: 313-541004X | C29: 八王子市中野上町5-1 | D29: 多摩 | E29: 八王子 | F29: 45469 | G29: 6 | H29: 430102 | I29: 事前 | J29: 40043443 | K29: みつば | L29: 11 | M29: 7 | N29: 11 | P29: 46001 | R29: 45991 | S29: 11 | T29: 308215 | U29: 25.11 | V29: 11 | W29: 40 | X29: 529975
A30: 29 | B30: 313-541005X | C30: 八王子市中野上町5-5 | D30: 多摩 | E30: 八王子 | F30: 45469 | G30: 6 | H30: 430103 | I30: 事前 | J30: 40043442
A31: 30 | B31: 313-541012X | C31: 八王子市中野上町3-18 | D31: 多摩 | E31: 八王子 | F31: 45469 | G31: 6 | H31: 430104 | I31: 事前 | J31: 40043445 | K31: 共立 | L31: 11 | M31: 8 | N31: 11 | R31: 45991 | S31: 11 | T31: 62070 | U31: 25.11 | V31: 11 | W31: 40 | X31: 128457
A32: 31 | B32: 313-541013X | C32: 八王子市中野山王3-20 | D32: 多摩 | E32: 八王子 | F32: 45469 | G32: 6 | H32: 430105 | I32: 事前 | J32: 40043444 | K32: 共立 | L32: 11 | M32: 8 | N32: 11 | R32: 45991 | S32: 11 | T32: 63110 | U32: 25.11 | V32: 11 | W32: 40 | X32: 130614
A33: 32 | B33: 313-541017X | C33: 小平市大沼町4-43 | D33: 多摩 | E33: 小平市 | F33: 45469 | G33: 6 | H33: 430106 | I33: 事前 | J33: 40043530 | K33: みつば | L33: 12 | M33: 7 | P33: 46001 | R33: 46022 | S33: 12 | T33: 344425 | U33: 25.12 | V33: 12 | W33: 40 | X33: 596382
A34: 33 | B34: 313-541020F | C34: 国分寺市東元町2-20 | D34: 多摩 | E34: 国分寺 | F34: 45469 | G34: 6 | H34: 430107 | I34: 事前 | J34: 40043463 | K34: 共立 | L34: 12 | M34: 8 | N34: 12 | P34: 46016 | R34: 46022 | S34: 12 | T34: 133590 | U34: 25.12 | V34: 12 | W34: 40 | X34: 226883
A35: 34 | B35: 313-541002X | C35: 八王子市中野上町4-24 | D35: 多摩 | E35: 八王子 | F35: 45470 | G35: 6 | H35: 430112 | I35: 事前 | J35: 40043577 | K35: みつば | L35: 11 | M35: 7 | N35: 11 | R35: 45991 | S35: 11 | T35: 111790 | U35: 25.11 | V35: 11 | W35: 40 | X35: 231338
A36: 35 | B36: 313-541006F | C36: 八王子市中野上町2-24 | D36: 多摩 | E36: 八王子 | F36: 45470 | G36: 6 | H36: 430113 | I36: 事前 | J36: 40043609 | K36: みつば | L36: 11 | M36: 7 | N36: 11 | P36: 46001 | R36: 45991 | S36: 11 | T36: 188745 | U36: 25.11 | V36: 11 | W36: 40 | X36: 340152
A37: 36 | B37: 313-541007X | C37: 八王子市中野上町4-43 | D37: 多摩 | E37: 八王子 | F37: 45470 | G37: 6 | H37: 430114 | I37: 事前 | J37: 40043568 | K37: みつば | L37: 11 | M37: 7 | N37: 11 | R37: 45991 | S37: 11 | T37: 82830 | U37: 25.11 | V37: 11 | W37: 40 | X37: 171399
A38: 37 | B38: 313-541008X | C38: 八王子市中野上町4-40 | D38: 多摩 | E38: 八王子 | F38: 45470 | G38: 6 | H38: 430115 | I38: 事前 | J38: 40043598 | K38: みつば | L38: 11 | M38: 7 | N38: 11 | R38: 45991 | S38: 11 | T38: 100490 | U38: 25.11 | V38: 11 | W38: 40 | X38: 207972
A39: 38 | B39: 313-541009F | C39: 八王子市中野上町2-32 | D39: 多摩 | E39: 八王子 | F39: 45470 | G39: 6 | H39: 430116 | I39: 事前 | J39: 40043602 | K39: 共立 | L39: 11 | M39: 8 | N39: 11 | R39: 45991 | S39: 11 | T39: 70250 | U39: 25.11 | V39: 11 | W39: 40 | X39: 145351
A40: 39 | B40: 313-541010X | C40: 八王子市中野上町4-10 | D40: 多摩 | E40: 八王子 | F40: 45470 | G40: 6 | H40: 430117 | I40: 事前 | J40: 40043590 | K40: 共立 | L40: 10 | M40: 8 | N40: 10 | U40: 25.1 | V40: 10 | W40: 40 | X40: 96622
...

Sheet 杭台帳(西)
A1: 整理番号 | B1: 工事番号 | C1: 住 所 | D1: NC区分 | E1: 住所（行政区） | F1: 受注日 | G1: 受注月 | H1: 受注番号 | I1: 区分 | J1: 発行番号 | K1: 外注先 | L1: 納品月 | M1: 外注 発注月 | N1: 外注納品月 | O1: 工期 | P1: 現場完了 予定日 | Q1: 現場予定日 | R1: 外注支払月 | S1: 外注支払月(月のみ) | T1: 外注支払額 | U1: 入金月 | V1: 入金月（月のみ） | W1: 精算 グループ | X1: 入金額 | Y1: 顧客会社担当者(後) | Z1: 申請 提出日 (ガスor役所)2 | AA1: 現場完了 予定日3 | AB1: 現場予定日（後） | AC1: 杭購入金額 | AE1: =SUM(W:W) -> 62611
A2: 1 | B2: 311-242242X | C2: 世田谷区玉川4-29 | D2: 西部 | E2: 世田谷 | F2: 44767 | G2: 7 | H2: 410001 | I2: 事前 | J2: 20015548 | K2: みつば | L2: 6 | M2: 4 | N2: 6 | O2: 未定 | P2: 45789 | R2: 45838 | S2: 6 | T2: 103235 | U2: 25.6 | V2: 6 | W2: 30 | X2: 252391
A3: 2 | B3: 311-042334X | C3: 三鷹市牟礼6-25 | D3: 西部 | E3: 三鷹市 | H3: 410002
A4: 3 | B4: 311-142157J | C4: 世田谷区赤堤1-36 | D4: 西部 | E4: 世田谷 | H4: 410003
A5: 4 | B5: 311-145026B | C5: 世田谷区玉川台2-28 | D5: 西部 | E5: 世田谷 | H5: 410004
A6: 5 | B6: 332-116370 | C6: 大田区東蒲田2-30 | D6: 南部 | E6: 大田区 | H6: 410005 | Y6: 8700
A7: 6 | B7: 311-042493X | C7: 世田谷区駒沢2-7 | D7: 西部 | E7: 世田谷 | H7: 410006
A8: 7 | B8: 311-042079W | C8: 世田谷区等々力2-9 | D8: 西部 | E8: 世田谷 | H8: 410007
A9: 8 | B9: 311-142137I | C9: 世田谷区経堂3-29 | D9: 西部 | E9: 世田谷 | H9: 410008
A10: 9 | B10: 113-041152Y | C10: 大田区大森中3-15-18 | D10: 南部 | E10: 大田区 | H10: 410009
A11: 10 | B11: 113-212032X | C11: 大田区中央4-13-8 | D11: 南部 | E11: 大田区 | H11: 410010
A12: 11 | B12: 311-443203X | C12: 三鷹市井の頭2-34 | D12: 西部 | E12: 三鷹市 | F12: 45324 | G12: 2 | H12: 410011 | I12: 事前 | J12: 30042041 | K12: 星 | L12: 7 | M12: 4 | N12: 7 | O12: 45566 | R12: 45869 | S12: 7 | T12: 109610 | U12: 25.7 | V12: 7 | W12: 30 | X12: 189640
A13: 12 | B13: 311-242100F | C13: 世田谷区用賀1-20 | D13: 西部 | E13: 世田谷 | H13: 410012
A14: 13 | B14: 113-342532X | C14: 大田区山王1-37-6 | D14: 南部 | E14: 大田区 | H14: 410013
A15: 14 | B15: 113-342533X | C15: 大田区山王1-29-9 | D15: 南部 | E15: 大田区 | H15: 410014
A16: 15 | B16: 113-319020X | C16: 大田区東糀谷4-10 | D16: 南部 | E16: 大田区 | H16: 410015
A17: 16 | B17: 332-105530 | C17: 大田区山王1-38 | D17: 南部 | E17: 大田区 | H17: 410016 | Y17: 8700
A18: 17 | B18: 113-311064X | C18: 大田区大森本町2-29-1 | D18: 南部 | E18: 大田区 | H18: 410017
A19: 18 | B19: 411-319094A | C19: 和光市下新倉4-4 | D19: 北部 | E19: 和光市 | H19: 410018
A20: 19 | B20: 113-541508X | C20: 大田区西六郷1-5-3 | D20: 南部 | E20: 大田区 | F20: 45433 | G20: 5 | H20: 410019 | I20: 事前 | J20: 40033208 | K20: みつば | M20: 2 | O20: 45931 | P20: -
A21: 20 | B21: 113-590023X | C21: 大田区蒲田3-24-4 | D21: 南部 | E21: 大田区 | F21: 45433 | G21: 5 | H21: 410020 | I21: 事前 | J21: 40036427 | K21: みつば | M21: 10 | O21: 45931 | P21: -
A22: 21 | B22: 113-590024X | C22: 大田区羽田4-4-29 | D22: 南部 | E22: 大田区 | F22: 45433 | G22: 5 | H22: 410021 | I22: 事前 | J22: 40036424 | K22: みつば | L22: 10 | M22: 9 | N22: 10 | O22: 45931 | R22: 45961 | S22: 10 | T22: 32750 | U22: 25.1 | V22: 10 | W22: 10 | X22: 58910
A23: 22 | B23: 113-541509X | C23: 大田区東蒲田2-29-16 | D23: 南部 | E23: 大田区 | F23: 45433 | G23: 5 | H23: 410022 | I23: 事前 | J23: 40036422 | K23: みつば | L23: 10 | M23: 7 | N23: 10 | O23: 45931 | P23: - | Q23: 8/18 | R23: 45961 | S23: 10 | T23: 106680 | U23: 25.11 | V23: 11 | W23: 10 | X23: 152876
A24: 23 | B24: 113-541512X | C24: 大田区東糀谷4-6-5 | D24: 南部 | E24: 大田区 | F24: 45433 | G24: 5 | H24: 410023 | I24: 事前 | J24: 40036423 | K24: みつば | L24: 10 | M24: 7 | N24: 10 | O24: 45931 | P24: - | Q24: 8/18 | R24: 45961 | S24: 10 | T24: 49300 | U24: 25.11 | V24: 11 | W24: 10 | X24: 83405
A25: 24 | B25: 113-541506X | C25: 大田区千鳥3-15-1 | D25: 南部 | E25: 大田区 | F25: 45435 | G25: 5 | H25: 410024 | I25: 事前 | J25: 40038124 | K25: みつば | L25: 9 | M25: 7 | N25: 9 | O25: 45931 | P25: - | Q25: 8/18 | R25: 45930 | S25: 9 | T25: 60270 | U25: 25.9 | V25: 9 | W25: 10 | X25: 102698
A26: 25 | B26: 113-541507X | C26: 大田区西蒲田7-60-9 | D26: 南部 | E26: 大田区 | F26: 45435 | G26: 5 | H26: 410025 | I26: 事前 | J26: 40038231 | K26: みつば | L26: 2 | M26: 7 | N26: 2 | O26: 45931 | P26: - | Q26: 8/18 | R26: 46081 | S26: 2 | T26: 123580 | U26: 26.2 | V26: 2 | W26: 10 | X26: 216005
A27: 26 | B27: 113-590022X | C27: 大田区大森北3-30-5 | D27: 南部 | E27: 大田区 | F27: 45440 | G27: 5 | H27: 410026 | I27: 事前 | J27: 40038797 | K27: みつば | L27: 8 | M27: 7 | N27: 8 | O27: 45931 | P27: - | Q27: 8/9 | R27: 45891 | S27: 8 | T27: 58310 | U27: 25.8 | V27: 8 | W27: 10 | X27: 99369
A28: 27 | B28: 113-541511X | C28: 大田区大森南3-8-1 | D28: 南部 | E28: 大田区 | F28: 45440 | G28: 5 | H28: 410027 | I28: 事前 | J28: 40038798 | K28: みつば | L28: 10 | M28: 7 | N28: 10 | O28: 45931 | P28: - | Q28: 7/25 | R28: 45961 | S28: 10 | T28: 213505 | U28: 25.11 | V28: 11 | W28: 10 | X28: 299306
A29: 28 | B29: 113-315022X | C29: 大田区多摩川2-12-25 | D29: 南部 | E29: 大田区 | H29: 410028
A30: 29 | B30: 113-312092X | C30: 大田区田園調布5-15-23 | D30: 南部 | E30: 大田区 | H30: 410029
A31: 30 | B31: 113-541510F | C31: 大田区大森東2-19-10 | D31: 南部 | E31: 大田区 | F31: 45448 | G31: 6 | H31: 410030 | I31: 事前 | J31: 40039941 | K31: みつば | M31: 6
A32: 31 | B32: 113-541505F | C32: 大田区西馬込2-34-1 | D32: 南部 | E32: 大田区 | F32: 45448 | G32: 6 | H32: 410031 | I32: 事前 | J32: 40039920 | K32: みつば | M32: 6
A33: 32 | B33: 411-316233A | C33: 新座市西堀1-11 | D33: 北部 | E33: 新座市 | H33: 410032 | Y33: 松田 | Z33: 8/5JP
A34: 33 | B34: 311-541030X | C34: 清瀬市元町2-10 | D34: 西部 | E34: 清瀬市 | F34: 45461 | G34: 6 | H34: 410033 | I34: 事前 | J34: 40041970 | K34: 星 | L34: 6 | M34: 4 | N34: 6 | O34: 45931 | P34: 45789 | R34: 45838 | S34: 6 | T34: 234250 | U34: 25.6 | V34: 6 | W34: 30 | X34: 401642
A35: 34 | B35: 311-541011X | C35: 東久留米市滝山6-2 | D35: 西部 | E35: 東久留 | F35: 45461 | G35: 6 | H35: 410034 | I35: 事前 | J35: 40041993 | K35: 星 | O35: 45931 | P35: -
A36: 35 | B36: 311-541010X | C36: 東久留米市滝山6-2 | D36: 西部 | E36: 東久留 | F36: 45461 | G36: 6 | H36: 410035 | I36: 事前 | J36: 40041995 | K36: 星 | O36: 45931 | P36: -
A37: 36 | B37: 311-641019X | C37: 東久留米市南沢3-1 | D37: 西部 | E37: 東久留 | F37: 45461 | G37: 6 | H37: 410036 | I37: 事前 | J37: 40041998 | K37: 星 | L37: 10 | M37: 7 | N37: 10 | O37: 46113 | R37: 45961 | S37: 10 | T37: 195030 | U37: 25.11 | V37: 11 | W37: 30 | X37: 337994
A38: 37 | B38: 311-641028X | C38: 東久留米市滝山6-1 | D38: 西部 | E38: 東久留 | F38: 45461 | G38: 6 | H38: 410037 | I38: 事前 | J38: 40042003 | K38: 星 | O38: 46113 | P38: -
A39: 38 | B39: 311-641029X | C39: 東久留米市滝山6-1 | D39: 西部 | E39: 東久留 | F39: 45461 | G39: 6 | H39: 410038 | I39: 事前 | J39: 40042005 | K39: 共立 | L39: 6 | M39: 4 | N39: 6 | O39: 46113 | P39: 45803 | R39: 45838 | S39: 6 | T39: 87760 | U39: 25.6 | V39: 6 | W39: 30 | X39: 151569
A40: 39 | B40: 311-641030X | C40: 東久留米市滝山7-19 | D40: 西部 | E40: 東久留 | F40: 45461 | G40: 6 | H40: 410039 | I40: 事前 | J40: 40042007 | K40: 共立 | L40: 6 | M40: 4 | N40: 6 | O40: 46113 | P40: 45803 | R40: 45838 | S40: 6 | T40: 81450 | U40: 25.6 | V40: 6 | W40: 30 | X40: 141740
...

Sheet 杭台帳(神)
A1: 整理番号 | B1: 工事番号 | C1: 住 所 | D1: NC区分 | E1: 住所（行政区） | F1: 受注日 | G1: 受注月 | H1: 受注番号 | I1: 区分 | J1: 発行番号 | K1: 外注先 | L1: 納品月 | M1: 外注 発注月 | N1: 外注納品月 | O1: 外注支払月 | P1: 外注支払月(月のみ) | Q1: 外注支払額 | R1: 入金月 | S1: 入金月（月のみ） | T1: 精算 グループ | U1: 入金額 | V1: 杭購入金額 | X1: =U646+U647+U724+U791 -> 730368
A2: 1 | B2: 622-108485 | C2: 幸区中幸町4-29-3 | D2: 神奈川 | E2: 幸区中 | H2: 425001
A3: 2 | B3: 512-042227X | C3: 港北区篠原町81 | D3: 神奈川 | E3: 港北区 | H3: 425003
A4: 3 | B4: 512-312060X | C4: 港北区富士塚1-9-3 | D4: 神奈川 | E4: 港北区 | F4: 45156 | G4: 8 | H4: 425005 | I4: 事前 | J4: 30017367 | K4: 共立 | M4: 8
A5: 4 | B5: 512-311041X | C5: 鶴見区矢向4-7-4 | D5: 神奈川 | E5: 鶴見区 | F5: 45156 | G5: 8 | H5: 425006 | I5: 事前 | J5: 30017032 | K5: 共立 | M5: 8
A6: 5 | B6: 511-219156X | C6: 横須賀市長沢3-7 | D6: 神奈川 | E6: 横須賀 | H6: 425008
A7: 6 | B7: 513-214018X | C7: 宮前区平5-8-35 | D7: 神奈川 | E7: 宮前区 | H7: 425010
A8: 7 | B8: 622-301632 | C8: 麻生区王禅寺西3-27 | D8: 神奈川 | E8: 麻生区 | H8: 425011
A9: 8 | B9: 512-443101T | C9: 神奈川区白幡向町17-15 | D9: 神奈川 | E9: 神奈川 | F9: 45359 | G9: 3 | H9: 425022 | I9: 事前 | J9: 30041252 | K9: みつば | M9: 3
A10: 9 | B10: 513-214006X | C10: 中原区今井仲町8-30 | D10: 神奈川 | E10: 中原区 | H10: 425031
A11: 10 | B11: 512-843145X | C11: 港北区篠原東3-17-4 | D11: 神奈川 | E11: 港北区 | H11: 425036
A12: 11 | B12: 513-314146X | C12: 宮前区西野川1-38 | D12: 神奈川 | E12: 宮前区 | H12: 425042
A13: 12 | B13: 513-214132X | C13: 宮前区有馬8-7 | D13: 神奈川 | E13: 宮前区 | H13: 425058
A14: 13 | B14: 513-219176X | C14: 宮前区潮見台9-2 | D14: 神奈川 | E14: 宮前区 | H14: 425059
A15: 14 | B15: 513-311010X | C15: 高津区下野毛3-14-5 | D15: 神奈川 | E15: 高津区 | H15: 425060
A16: 15 | B16: 513-314005X | C16: 多摩区宿河原7-8-1 | D16: 神奈川 | E16: 多摩区 | F16: 45391 | G16: 4 | H16: 425064 | I16: 事前 | J16: 40001018 | K16: みつば | M16: 4 | N16: 4 | O16: 45402 | P16: 4 | Q16: 48990
A17: 16 | B17: 513-219155X | C17: 宮前区菅生6-2-4 | D17: 神奈川 | E17: 宮前区 | H17: 425077
A18: 17 | B18: 513-212007X | C18: 宮前区馬絹4-11-37 | D18: 神奈川 | E18: 宮前区 | H18: 425094
A19: 18 | B19: 513-412016X | C19: 宮前区鷺沼1-18-10 | D19: 神奈川 | E19: 宮前区 | F19: 45413 | G19: 5 | H19: 425101 | I19: 事前 | J19: 30049159 | K19: 共立 | L19: 5 | M19: 5 | N19: 5 | O19: 45432 | P19: 5 | Q19: 33860 | R19: 25.8 | S19: 8 | T19: 27 | U19: 65097
A20: 19 | B20: 622-400802 | C20: 高津区溝口5-7-10 | D20: 神奈川 | E20: 高津区 | F20: 45432 | G20: 5 | H20: 425125 | I20: 事前 | J20: 40027244 | K20: 共立 | L20: 6 | M20: 5 | N20: 5
A21: 20 | B21: 512-411028X | C21: 神奈川区入江1-11-3 | D21: 神奈川 | E21: 神奈川 | F21: 45443 | G21: 5 | H21: 425157 | I21: 事前 | J21: 40026948 | K21: 共立 | L21: 6 | M21: 5 | N21: 6 | R21: 25.9 | S21: 9 | T21: 21 | U21: 73776
A22: 21 | B22: 622-400946 | C22: 高津区下野毛3-5-10 | D22: 神奈川 | E22: 高津区 | F22: 45443 | G22: 5 | H22: 425161 | I22: 事前 | J22: 40039216 | K22: 共立 | L22: 6 | M22: 5 | N22: 6
A23: 22 | B23: 513-214194X | C23: 宮前区西野川1-18 | D23: 神奈川 | E23: 宮前区 | H23: 425162
A24: 23 | B24: 512-403008M | C24: 港北区蓑輪町1-25-25 | D24: 神奈川 | E24: 港北区 | F24: 45432 | G24: 5 | H24: 425163 | I24: 事前 | J24: 40027288 | K24: みつば | L24: 5 | M24: 5 | N24: 6 | O24: 45463 | P24: 6 | Q24: 31950 | R24: 25.9 | S24: 9 | T24: 23 | U24: 59683
A25: 24 | B25: 513-211063X | C25: 多摩区宿河原1-23-5 | D25: 神奈川 | E25: 多摩区 | H25: 425165
A26: 25 | B26: 622-211100 | C26: 中原区上平間594 | D26: 神奈川 | E26: 中原区 | H26: 425172
A27: 26 | B27: 622-210020 | C27: 中原区新城1-9 | D27: 神奈川 | E27: 中原区 | H27: 425173
A28: 27 | B28: 513-142161X | C28: 川崎区大島1-26-7 | D28: 神奈川 | E28: 川崎区 | H28: 425205
A29: 28 | B29: 512-319282A | C29: 都筑区池辺町2352 | D29: 神奈川 | E29: 都筑区 | H29: 425269
A30: 29 | B30: 513-403014M | C30: 多摩区登戸918-6 | D30: 神奈川 | E30: 多摩区 | F30: 45482 | G30: 7 | H30: 425376 | I30: 事前 | J30: 40044507 | K30: 共立 | L30: 12 | M30: 7 | N30: 12 | O30: 46022 | P30: 12 | Q30: 28000 | R30: 25.12 | S30: 12 | T30: 23 | U30: 46413
A31: 30 | B31: 513-314111X | C31: 宮前区馬絹4-13-13 | D31: 神奈川 | E31: 宮前区 | H31: 425404
A32: 31 | B32: 513-319044X | C32: 宮前区梶ヶ谷1385 | D32: 神奈川 | E32: 宮前区 | F32: 45485 | G32: 7 | H32: 425408 | I32: 事前 | J32: 40045533 | K32: 共立 | M32: 7 | N32: 8
A33: 32 | B33: 513-142286X | C33: 高津区溝口5-10-9 | D33: 神奈川 | E33: 高津区 | H33: 425433
A34: 33 | B34: 513-142122X | C34: 幸区鹿島田1-5-16 | D34: 神奈川 | E34: 幸区鹿 | H34: 425458
A35: 34 | B35: 511-243139S | C35: 横須賀市西逸見町2-79～2-75 | D35: 神奈川 | E35: 横須賀 | H35: 425459
A36: 35 | B36: 512-219229X | C36: 都筑区牛久保町1893-7 | D36: 神奈川 | E36: 都筑区 | H36: 425460
A37: 36 | B37: 513-014094A | C37: 多摩区菅北浦1-11 | D37: 神奈川 | E37: 多摩区 | H37: 425463
A38: 37 | B38: 511-342110J | C38: 横須賀市小川町3-4 | D38: 神奈川 | E38: 横須賀 | H38: 425512
A39: 38 | B39: 513-342108P | C39: 麻生区百合丘1-24-38 | D39: 神奈川 | E39: 麻生区 | H39: 425532
A40: 39 | B40: 513-214129A | C40: 宮前区西野川1-12 | D40: 神奈川 | E40: 宮前区 | H40: 425542
...

Sheet 杭台帳(事後)(多)
A1: 整理番号 | B1: 工事番号 | C1: 住 所 | D1: NC区分 | E1: 住所（行政区） | F1: 工期 | G1: 製本受領 | H1: 多摩フリ3 | I1: 受注日(後) | J1: 受注月(後) | K1: 受注番号(後) | L1: 区分(後) | M1: 発行番号(後) | N1: 外注先(後) | O1: 納品 月(後) | P1: 外注 発注月(後) | Q1: 外注納品月(後) | R1: 復元杭引渡日 | S1: 製本受領2 | T1: 市提出 | U1: 杭購入金額 | V1: 外注支払月(後) | W1: 外注支払月(後)(月のみ) | X1: 外注支払額(後) | Y1: 入金月(後) | Z1: 入金月(後)（月のみ） | AA1: 精算 グループ(後) | AB1: 入金額(後) | AF1: =SUM(AA:AA) -> 33752
A2: 1 | B2: 313-343065X | C2: 国分寺市本多5-25 | D2: 多摩 | E2: 国分寺 | G2: 45827 | L2: 事後 | AF2: =AF1+'杭台帳(多)'!AF1 -> 1.2678268e+08
A3: 2 | B3: 313-343014X | C3: 立川市栄町3-24 | D3: 多摩 | E3: 立川市 | L3: 事後
A4: 3 | B4: 313-343017X | C4: 東村山市秋津町5-6 | D4: 多摩 | E4: 東村山 | L4: 事後
A5: 4 | B5: 313-242114E | C5: 八王子市中野山王1-5 | D5: 多摩 | E5: 八王子 | I5: 45075 | J5: 5 | L5: 事後 | M5: 30001889 | N5: みつば | O5: 1 | P5: 8 | Q5: 1 | R5: 45742 | T5: 46035 | Y5: 26.1 | Z5: 1 | AA5: 40 | AB5: 688424
A6: 5 | B6: 313-042102X | C6: 八王子市平岡町36 | D6: 多摩 | E6: 八王子 | I6: 45141 | J6: 8 | L6: 事後 | M6: 30015796 | N6: 共立 | O6: 9 | P6: 9 | Q6: 9 | U6: 7050 | V6: 45922 | W6: 9 | X6: 516760 | Y6: 25.9 | Z6: 9 | AA6: 40 | AB6: 1048415
A7: 6 | B7: 313-986704X | C7: 八王子市南町3 | D7: 多摩 | E7: 八王子 | I7: 45152 | J7: 8 | L7: 事後 | M7: 30019061 | N7: みつば | O7: 8 | P7: 12 | Q7: 8 | S7: 45908 | T7: 45909 | V7: 45890 | W7: 8 | X7: 258000 | Y7: 25.8 | Z7: 8 | AA7: 40 | AB7: 451659
A8: 7 | B8: 313-486721C | C8: 東村山市本町1-16 | D8: 多摩 | E8: 東村山 | L8: 事後
A9: 8 | B9: 313-443034X | C9: 小平市仲町291 | D9: 多摩 | E9: 小平市 | L9: 事後
A10: 9 | B10: 313-443033X | C10: 小平市小川西町3-12 | D10: 多摩 | E10: 小平市 | L10: 事後
A11: 10 | B11: 313-443032X | C11: 小平市花小金井1-17 | D11: 多摩 | E11: 小平市 | L11: 事後
A12: 11 | B12: 313-443031X | C12: 小平市学園東町3-1 | D12: 多摩 | E12: 小平市 | G12: 45873 | L12: 事後
A13: 12 | B13: 313-443038X | C13: 国分寺市泉町1-10 | D13: 多摩 | E13: 国分寺 | L13: 事後
A14: 13 | B14: 313-443043X | C14: 国立市中1-14 | D14: 多摩 | E14: 国立市 | L14: 事後
A15: 14 | B15: 313-443044X | C15: 国立市西2-3 | D15: 多摩 | E15: 国立市 | L15: 事後
A16: 15 | B16: 313-443015X | C16: 八王子市めじろ台1-41 | D16: 多摩 | E16: 八王子 | L16: 事後
A17: 16 | B17: 313-443048X | C17: 東大和市南街2-101 | D17: 多摩 | E17: 東大和 | L17: 事後
A18: 17 | B18: 313-443040X | C18: 国分寺市東元町2-7 | D18: 多摩 | E18: 国分寺 | G18: 45834 | L18: 事後
A19: 18 | B19: 313-443039X | C19: 国分寺市東元町2-14 | D19: 多摩 | E19: 国分寺 | G19: 45834 | L19: 事後
A20: 19 | B20: 313-443049X | C20: 東大和市萩山町2-20 | D20: 多摩 | E20: 東大和 | L20: 事後
A21: 20 | B21: 313-242014M | C21: 国分寺市東恋ヶ窪2-23 | D21: 多摩 | E21: 国分寺 | I21: 45342 | J21: 2 | L21: 事後 | M21: 30044178 | N21: 共立 | P21: 11 | R21: 45344
A22: 21 | B22: 313-486723A | C22: 多摩市鶴牧5-31 | D22: 多摩 | E22: 多摩市 | L22: 事後
A23: 22 | B23: 313-471713X | C23: 多摩市関戸5-16 | D23: 多摩 | E23: 多摩市 | F23: 46027 | L23: 事後
A24: 23 | B24: 313-342033M | C24: 日野市東平山1-7 | D24: 多摩 | E24: 日野市 | I24: 45420 | J24: 5 | L24: 事後 | M24: 40019762 | N24: 共立 | O24: 7 | P24: 5 | Q24: 7 | V24: 45860 | W24: 7 | X24: 30550 | Y24: 25.7 | Z24: 7 | AA24: 40 | AB24: 65565
A25: 24 | B25: 313-342043X | C25: 小平市学園西町3-23 | D25: 多摩 | E25: 小平市 | I25: 45442 | J25: 5 | L25: 事後 | M25: 40038988 | N25: 西都 | P25: 6
A26: 25 | B26: 313-443051X | C26: 国分寺市東元町3-21 | D26: 多摩 | E26: 国分寺 | L26: 事後
A27: 26 | B27: 313-541001X | C27: 八王子市中野上町4-28 | D27: 多摩 | E27: 八王子 | L27: 事後
A28: 27 | B28: 313-541003X | C28: 八王子市中野上町5-10 | D28: 多摩 | E28: 八王子 | G28: 46001 | L28: 事後
A29: 28 | B29: 313-541004X | C29: 八王子市中野上町5-1 | D29: 多摩 | E29: 八王子 | G29: 46001 | L29: 事後
A30: 29 | B30: 313-541005X | C30: 八王子市中野上町5-5 | D30: 多摩 | E30: 八王子 | L30: 事後
A31: 30 | B31: 313-541012X | C31: 八王子市中野上町3-18 | D31: 多摩 | E31: 八王子 | L31: 事後
A32: 31 | B32: 313-541013X | C32: 八王子市中野山王3-20 | D32: 多摩 | E32: 八王子 | L32: 事後
A33: 32 | B33: 313-541017X | C33: 小平市大沼町4-43 | D33: 多摩 | E33: 小平市 | G33: 46001 | L33: 事後
A34: 33 | B34: 313-541020F | C34: 国分寺市東元町2-20 | D34: 多摩 | E34: 国分寺 | G34: 46016 | L34: 事後
A35: 34 | B35: 313-541002X | C35: 八王子市中野上町4-24 | D35: 多摩 | E35: 八王子 | L35: 事後
A36: 35 | B36: 313-541006F | C36: 八王子市中野上町2-24 | D36: 多摩 | E36: 八王子 | G36: 46001 | L36: 事後
A37: 36 | B37: 313-541007X | C37: 八王子市中野上町4-43 | D37: 多摩 | E37: 八王子 | L37: 事後
A38: 37 | B38: 313-541008X | C38: 八王子市中野上町4-40 | D38: 多摩 | E38: 八王子 | L38: 事後
A39: 38 | B39: 313-541009F | C39: 八王子市中野上町2-32 | D39: 多摩 | E39: 八王子 | L39: 事後
A40: 39 | B40: 313-541010X | C40: 八王子市中野上町4-10 | D40: 多摩 | E40: 八王子 | L40: 事後
...

Sheet 杭台帳(事後)(西)
A1: 整理番号 | B1: 工事番号 | C1: 住 所 | D1: NC区分 | E1: 住所（行政区） | F1: 工期 | G1: 現場完了 予定日 | H1: 現場予定日 | I1: 受注日(後) | J1: 受注月(後) | K1: 受注番号(後) | L1: 区分(後) | M1: 顧客会社担当者(後) | N1: 発行番号(後) | O1: 外注先(後) | P1: 納品 月(後) | Q1: 外注 発注月(後) | R1: 外注納品月(後) | S1: 申請 提出日 (ガスor役所)2 | T1: 現場完了 予定日3 | U1: 現場予定日（後） | V1: 杭購入金額 | W1: 外注支払月(後) | X1: 外注支払月(後)(月のみ) | Y1: 外注支払額(後) | Z1: 入金月(後) | AA1: 入金月(後)（月のみ） | AB1: 精算 グループ(後) | AC1: 入金額(後) | AE1: =SUM(Z:Z) -> 9088.09
A2: 1 | B2: 311-242242X | C2: 世田谷区玉川4-29 | D2: 西部 | E2: 世田谷 | F2: 未定 | G2: 45789 | AE2: =AE1+'杭台帳(西)'!AE1 -> 71699.09
A3: 2 | B3: 311-042334X | C3: 三鷹市牟礼6-25 | D3: 西部 | E3: 三鷹市 | I3: 44851 | J3: 10 | L3: 事後 | O3: 共立 | Q3: 10
A4: 3 | B4: 311-142157J | C4: 世田谷区赤堤1-36 | D4: 西部 | E4: 世田谷 | I4: 44908 | J4: 12 | L4: 事後 | O4: 共立 | Q4: 2
A5: 4 | B5: 311-145026B | C5: 世田谷区玉川台2-28 | D5: 西部 | E5: 世田谷 | I5: 44940 | J5: 1 | L5: 事後 | O5: 共立 | Q5: 1
A6: 5 | B6: 332-116370 | C6: 大田区東蒲田2-30 | D6: 南部 | E6: 大田区 | I6: 45019 | J6: 4 | L6: 事後 | M6: 8700 | O6: 共立 | Q6: 4
A7: 6 | B7: 311-042493X | C7: 世田谷区駒沢2-7 | D7: 西部 | E7: 世田谷 | I7: 45146 | J7: 8 | L7: 事後 | O7: みつば | Q7: 8
A8: 7 | B8: 311-042079W | C8: 世田谷区等々力2-9 | D8: 西部 | E8: 世田谷 | I8: 45216 | J8: 10 | L8: 事後 | N8: 300279776 | O8: 共立 | Q8: 10
A9: 8 | B9: 311-142137I | C9: 世田谷区経堂3-29 | D9: 西部 | E9: 世田谷 | I9: 45217 | J9: 10 | L9: 事後 | N9: 30028292 | O9: 共立 | Q9: 10
A10: 9 | B10: 113-041152Y | C10: 大田区大森中3-15-18 | D10: 南部 | E10: 大田区 | I10: 45300 | J10: 1 | L10: 事後 | N10: 30038651 | O10: 共立 | Q10: 1
A11: 10 | B11: 113-212032X | C11: 大田区中央4-13-8 | D11: 南部 | E11: 大田区 | I11: 45322 | J11: 1 | L11: 事後 | N11: 30041726 | O11: 共立 | Q11: 2
A12: 11 | B12: 311-443203X | C12: 三鷹市井の頭2-34 | D12: 西部 | E12: 三鷹市 | F12: 45566
A13: 12 | B13: 311-242100F | C13: 世田谷区用賀1-20 | D13: 西部 | E13: 世田谷 | I13: 45383 | J13: 4 | L13: 事後 | N13: 30043415 | O13: 共立 | Q13: 2
A14: 13 | B14: 113-342532X | C14: 大田区山王1-37-6 | D14: 南部 | E14: 大田区 | I14: 45384 | J14: 4 | L14: 事後 | N14: 40000155 | O14: 共立 | Q14: 4
A15: 14 | B15: 113-342533X | C15: 大田区山王1-29-9 | D15: 南部 | E15: 大田区 | I15: 45385 | J15: 4 | L15: 事後 | N15: 40000156 | O15: 共立 | Q15: 4
A16: 15 | B16: 113-319020X | C16: 大田区東糀谷4-10 | D16: 南部 | E16: 大田区 | I16: 45390 | J16: 4 | L16: 事後 | N16: 40000346 | O16: みつば | Q16: 4
A17: 16 | B17: 332-105530 | C17: 大田区山王1-38 | D17: 南部 | E17: 大田区 | I17: 45393 | J17: 4 | L17: 事後 | M17: 8700 | O17: みつば | P17: 6 | Q17: 4 | R17: 6 | W17: 45838 | X17: 6 | Y17: 139450 | Z17: 25.6 | AA17: 6 | AB17: 101 | AC17: 364416.01
A18: 17 | B18: 113-311064X | C18: 大田区大森本町2-29-1 | D18: 南部 | E18: 大田区 | I18: 45425 | J18: 5 | L18: 事後 | N18: 40003683 | O18: みつば | Q18: 4
A19: 18 | B19: 411-319094A | C19: 和光市下新倉4-4 | D19: 北部 | E19: 和光市 | I19: 45443 | J19: 5 | L19: 事後 | N19: 40023701 | O19: 共立 | Q19: 5
A20: 19 | B20: 113-541508X | C20: 大田区西六郷1-5-3 | D20: 南部 | E20: 大田区 | F20: 45931 | G20: -
A21: 20 | B21: 113-590023X | C21: 大田区蒲田3-24-4 | D21: 南部 | E21: 大田区 | F21: 45931 | G21: -
A22: 21 | B22: 113-590024X | C22: 大田区羽田4-4-29 | D22: 南部 | E22: 大田区 | F22: 45931
A23: 22 | B23: 113-541509X | C23: 大田区東蒲田2-29-16 | D23: 南部 | E23: 大田区 | F23: 45931 | G23: - | H23: 8/18
A24: 23 | B24: 113-541512X | C24: 大田区東糀谷4-6-5 | D24: 南部 | E24: 大田区 | F24: 45931 | G24: - | H24: 8/18
A25: 24 | B25: 113-541506X | C25: 大田区千鳥3-15-1 | D25: 南部 | E25: 大田区 | F25: 45931 | G25: - | H25: 8/18
A26: 25 | B26: 113-541507X | C26: 大田区西蒲田7-60-9 | D26: 南部 | E26: 大田区 | F26: 45931 | G26: - | H26: 8/18
A27: 26 | B27: 113-590022X | C27: 大田区大森北3-30-5 | D27: 南部 | E27: 大田区 | F27: 45931 | G27: - | H27: 8/9
A28: 27 | B28: 113-541511X | C28: 大田区大森南3-8-1 | D28: 南部 | E28: 大田区 | F28: 45931 | G28: - | H28: 7/25
A29: 28 | B29: 113-315022X | C29: 大田区多摩川2-12-25 | D29: 南部 | E29: 大田区 | I29: 45643 | J29: 12 | L29: 事後 | N29: 40039254 | O29: みつば | Q29: 5
A30: 29 | B30: 113-312092X | C30: 大田区田園調布5-15-23 | D30: 南部 | E30: 大田区 | I30: 45643 | J30: 12 | L30: 事後 | N30: 40039291 | O30: みつば | Q30: 5
A31: 30 | B31: 113-541510F | C31: 大田区大森東2-19-10 | D31: 南部 | E31: 大田区
A32: 31 | B32: 113-541505F | C32: 大田区西馬込2-34-1 | D32: 南部 | E32: 大田区
A33: 32 | B33: 411-316233A | C33: 新座市西堀1-11 | D33: 北部 | E33: 新座市 | I33: 45684 | J33: 1 | L33: 事後 | M33: 松田 | N33: 40040471 | O33: 共立 | P33: 8 | Q33: 6 | R33: 7 | S33: 8/5JP | W33: 45869 | X33: 7 | Y33: 68490 | Z33: 25.8 | AA33: 8 | AB33: 30 | AC33: 136391
A34: 33 | B34: 311-541030X | C34: 清瀬市元町2-10 | D34: 西部 | E34: 清瀬市 | F34: 45931 | G34: 45789
A35: 34 | B35: 311-541011X | C35: 東久留米市滝山6-2 | D35: 西部 | E35: 東久留 | F35: 45931 | G35: -
A36: 35 | B36: 311-541010X | C36: 東久留米市滝山6-2 | D36: 西部 | E36: 東久留 | F36: 45931 | G36: -
A37: 36 | B37: 311-641019X | C37: 東久留米市南沢3-1 | D37: 西部 | E37: 東久留 | F37: 46113
A38: 37 | B38: 311-641028X | C38: 東久留米市滝山6-1 | D38: 西部 | E38: 東久留 | F38: 46113 | G38: -
A39: 38 | B39: 311-641029X | C39: 東久留米市滝山6-1 | D39: 西部 | E39: 東久留 | F39: 46113 | G39: 45803
A40: 39 | B40: 311-641030X | C40: 東久留米市滝山7-19 | D40: 西部 | E40: 東久留 | F40: 46113 | G40: 45803
...

Sheet 杭台帳(事後)(神)
A1: 整理番号 | B1: 工事番号 | C1: 住 所 | D1: NC区分 | E1: 住所（行政区） | F1: 受注日(後) | G1: 受注月(後) | H1: 受注番号(後) | I1: 区分(後) | J1: 発行番号(後) | K1: 外注先(後) | L1: 納品 月(後) | M1: 外注 発注月(後) | N1: 外注納品月(後) | O1: 杭購入金額 | P1: 外注支払月(後) | Q1: 外注支払月(後)(月のみ) | R1: 外注支払額(後) | S1: 入金月(後) | T1: 入金月(後)（月のみ） | U1: 精算 グループ(後) | V1: 入金額(後) | Y1: =SUM(U:U) -> 11060
A2: 1 | B2: 622-108485 | C2: 幸区中幸町4-29-3 | D2: 神奈川 | E2: 幸区中 | F2: 45113 | G2: 7 | I2: 事後 | J2: 30013944 | K2: 共立 | M2: 7 | Y2: =Y1+'杭台帳(神)'!Y1 -> 11060
A3: 2 | B3: 512-042227X | C3: 港北区篠原町81 | D3: 神奈川 | E3: 港北区 | F3: 45143 | G3: 8 | I3: 事後 | J3: 30018603 | K3: 共立 | M3: 8
A4: 3 | B4: 512-312060X | C4: 港北区富士塚1-9-3 | D4: 神奈川 | E4: 港北区
A5: 4 | B5: 512-311041X | C5: 鶴見区矢向4-7-4 | D5: 神奈川 | E5: 鶴見区
A6: 5 | B6: 511-219156X | C6: 横須賀市長沢3-7 | D6: 神奈川 | E6: 横須賀 | F6: 45194 | G6: 9 | I6: 事後 | J6: 30024979 | K6: みつば | L6: 7 | M6: 9 | N6: 7 | P6: 45867 | Q6: 7 | R6: 117310 | S6: 25.7 | T6: 7 | U6: 20 | V6: 297372
A7: 6 | B7: 513-214018X | C7: 宮前区平5-8-35 | D7: 神奈川 | E7: 宮前区 | F7: 45217 | G7: 10 | I7: 事後 | J7: 30027716 | K7: みつば | M7: 10
A8: 7 | B8: 622-301632 | C8: 麻生区王禅寺西3-27 | D8: 神奈川 | E8: 麻生区 | F8: 45225 | G8: 10 | I8: 事後 | J8: 30029509 | K8: みつば | M8: 10
A9: 8 | B9: 512-443101T | C9: 神奈川区白幡向町17-15 | D9: 神奈川 | E9: 神奈川
A10: 9 | B10: 513-214006X | C10: 中原区今井仲町8-30 | D10: 神奈川 | E10: 中原区 | F10: 45341 | G10: 2 | I10: 事後 | J10: 30043686 | K10: 占部 | M10: 2
A11: 10 | B11: 512-843145X | C11: 港北区篠原東3-17-4 | D11: 神奈川 | E11: 港北区 | F11: 45341 | G11: 2 | I11: 事後 | J11: 30043675 | K11: 共立 | M11: 2
A12: 11 | B12: 513-314146X | C12: 宮前区西野川1-38 | D12: 神奈川 | E12: 宮前区 | F12: 45341 | G12: 2 | I12: 事後 | J12: 30043720 | K12: 共立 | L12: 6 | M12: 2 | N12: 6 | S12: 25.9 | T12: 9 | U12: 21 | V12: 139623
A13: 12 | B13: 513-214132X | C13: 宮前区有馬8-7 | D13: 神奈川 | E13: 宮前区 | F13: 45341 | G13: 2 | I13: 事後 | J13: 30043688 | K13: みつば | L13: 5 | M13: 2 | N13: 5 | P13: 45432 | Q13: 5 | R13: 69950 | S13: 25.9 | T13: 9 | U13: 21 | V13: 138194
A14: 13 | B14: 513-219176X | C14: 宮前区潮見台9-2 | D14: 神奈川 | E14: 宮前区 | F14: 45341 | G14: 2 | I14: 事後 | J14: 30043691 | K14: みつば | L14: 5 | M14: 2 | N14: 5 | P14: 45797 | Q14: 5 | R14: 303000 | S14: 25.6 | T14: 6 | U14: 21 | V14: 463356
A15: 14 | B15: 513-311010X | C15: 高津区下野毛3-14-5 | D15: 神奈川 | E15: 高津区 | F15: 45341 | G15: 2 | I15: 事後 | J15: 30043713 | K15: みつば | M15: 2
